Workbook
Name ARISBin1: 'Chinook All Ages Proportions'!$L$6,'Chinook All Ages Proportions'!$M$6,'Chinook All Ages Proportions'!$N$6:$R$6

Sheet 1. Mixture Model Inputs
A1: Inputs from Mixture Model Results | AT1: Method Lookup
A2: 2023 | AT2: ML - Unweighted | AU2: Unweighted
A3: Mission Date | B3: Mixture Model | AH3: Mean Length and Sigma Values | AP3: Number of Groups | AQ3: Select Method | AR3: SalmonProp Lookup | AT3: ML - Weighted | AU3: Weighted
B4: Chinook Adult Percentages | J4: Chinook Jack Percentages | R4: Pink Percentages | Z4: Salmon Percentages | AH4: Pink | AJ4: Sockeye | AL4: Chinook | AN4: Chinook Jacks | AT4: Spline DFA | AU4: SplineDFA
B5: LB Bin 1 Aim 1 | C5: LB Bin 1 Aim 2 | D5: LB Bin 1 Combined | E5: LB Bin 2 | F5: LB Bin 3 | G5: RB Bin 1 | H5: RB Bin 2 | I5: RB Bin 3 | J5: LB Bin 1 Aim 1 | K5: LB Bin 1 Aim 2 | L5: LB Bin 1 Combined | M5: LB Bin 2 | N5: LB Bin 3 | O5: RB Bin 1 | P5: RB Bin 2 | Q5: RB Bin 3 | R5: LB Bin 1 Aim 1 | S5: LB Bin 1 Aim 2 | T5: LB Bin 1 Combined | U5: LB Bin 2 | V5: LB Bin 3 | W5: RB Bin 1 | X5: RB Bin 2 | Y5: RB Bin 3 | Z5: LB Bin 1 Aim 1 | AA5: LB Bin 1 Aim 2 | AB5: LB Bin 1 Combined | AC5: LB Bin 2 | AD5: LB Bin 3 | AE5: RB Bin 1 | AF5: RB Bin 2 | AG5: RB Bin 3 | AH5: Mean Length | AI5: Sigma | AJ5: Mean Length | AK5: Sigma | AL5: Mean Length | AM5: Sigma | AN5: Mean Length | AO5: Sigma | AT5: Spline Threshold | AU5: SplineThreshold
A6: ='[1]Passage Estimates'!$A6 -> 45108 | B6: {=IF(ISBLANK($AQ6), "", INDEX([2]SalmonProps!$A$2:$AA$10001,MATCH(1,($A6=[2]SalmonProps!$A$2:$A$10001)*(1=[2]SalmonProps!$C$2:$C$10001)*(1=[2]SalmonProps!$D$2:$D$10001)*("A1" = [2]SalmonProps!$B$2:$B$10001)*($AP6 = [2]SalmonProps!$F$2:$F$10001) *($AR6 = [2]SalmonProps!$G$2:$G$10001),0), 17))} -> 0 | C6: {=IF(ISBLANK($AQ6), "", INDEX([2]SalmonProps!$A$2:$AA$10001,MATCH(1,($A6=[2]SalmonProps!$A$2:$A$10001)*(1=[2]SalmonProps!$C$2:$C$10001)*(2=[2]SalmonProps!$D$2:$D$10001)*("A1" = [2]SalmonProps!$B$2:$B$10001)*($AP6 = [2]SalmonProps!$F$2:$F$10001) *($AR6 = [2]SalmonProps!$G$2:$G$10001),0), 17))} -> 0 | D6: {=IF(ISBLANK($AQ6), "", INDEX([2]SalmonProps!$A$2:$AA$10001,MATCH(1,($A6=[2]SalmonProps!$A$2:$A$10001)*(1=[2]SalmonProps!$C$2:$C$10001)*("1&2"=[2]SalmonProps!$D$2:$D$10001)*("A1" = [2]SalmonProps!$B$2:$B$10001)*($AP6 = [2]SalmonProps!$F$2:$F$10001) *($AR6 = [2]SalmonProps!$G$2:$G$10001),0), 17))} -> 0 | E6: {=IF(ISBLANK($AQ6), "", INDEX([2]SalmonProps!$A$2:$AA$10001,MATCH(1,($A6=[2]SalmonProps!$A$2:$A$10001)*(2=[2]SalmonProps!$C$2:$C$10001)*(3=[2]SalmonProps!$D$2:$D$10001)*("A1" = [2]SalmonProps!$B$2:$B$10001)*($AP6 = [2]SalmonProps!$F$2:$F$10001) *($AR6 = [2]SalmonProps!$G$2:$G$10001),0), 17))} -> 0.0304 | F6: {=IF(ISBLANK($AQ6), "", INDEX([2]SalmonProps!$A$2:$AA$10001,MATCH(1,($A6=[2]SalmonProps!$A$2:$A$10001)*(3=[2]SalmonProps!$C$2:$C$10001)*(3=[2]SalmonProps!$D$2:$D$10001)*("A1" = [2]SalmonProps!$B$2:$B$10001)*($AP6 = [2]SalmonProps!$F$2:$F$10001) *($AR6 = [2]SalmonProps!$G$2:$G$10001),0), 17))} -> 0.1186 | G6: 0 | H6: 0.0333 | I6: 0.0694 | J6: {=IF(ISBLANK($AQ6), "", INDEX([2]SalmonProps!$A$2:$AA$10001,MATCH(1,($A6=[2]SalmonProps!$A$2:$A$10001)*(1=[2]SalmonProps!$C$2:$C$10001)*(1=[2]SalmonProps!$D$2:$D$10001)*("A1" = [2]SalmonProps!$B$2:$B$10001)*($AP6 = [2]SalmonProps!$F$2:$F$10001) *($AR6 = [2]SalmonProps!$G$2:$G$10001),0), 19))} -> NA | K6: {=IF(ISBLANK($AQ6), "", INDEX([2]SalmonProps!$A$2:$AA$10001,MATCH(1,($A6=[2]SalmonProps!$A$2:$A$10001)*(1=[2]SalmonProps!$C$2:$C$10001)*(2=[2]SalmonProps!$D$2:$D$10001)*("A1" = [2]SalmonProps!$B$2:$B$10001)*($AP6 = [2]SalmonProps!$F$2:$F$10001) *($AR6 = [2]SalmonProps!$G$2:$G$10001),0), 19))} -> NA | L6: {=IF(ISBLANK($AQ6), "", INDEX([2]SalmonProps!$A$2:$AA$10001,MATCH(1,($A6=[2]SalmonProps!$A$2:$A$10001)*(1=[2]SalmonProps!$C$2:$C$10001)*("1&2"=[2]SalmonProps!$D$2:$D$10001)*("A1" = [2]SalmonProps!$B$2:$B$10001)*($AP6 = [2]SalmonProps!$F$2:$F$10001) *($AR6 = [2]SalmonProps!$G$2:$G$10001),0), 19))} -> NA | M6: {=IF(ISBLANK($AQ6), "", INDEX([2]SalmonProps!$A$2:$AA$10001,MATCH(1,($A6=[2]SalmonProps!$A$2:$A$10001)*(2=[2]SalmonProps!$C$2:$C$10001)*(3=[2]SalmonProps!$D$2:$D$10001)*("A1" = [2]SalmonProps!$B$2:$B$10001)*($AP6 = [2]SalmonProps!$F$2:$F$10001) *($AR6 = [2]SalmonProps!$G$2:$G$10001),0), 19))} -> NA | N6: {=IF(ISBLANK($AQ6), "", INDEX([2]SalmonProps!$A$2:$AA$10001,MATCH(1,($A6=[2]SalmonProps!$A$2:$A$10001)*(3=[2]SalmonProps!$C$2:$C$10001)*(3=[2]SalmonProps!$D$2:$D$10001)*("A1" = [2]SalmonProps!$B$2:$B$10001)*($AP6 = [2]SalmonProps!$F$2:$F$10001) *($AR6 = [2]SalmonProps!$G$2:$G$10001),0), 19))} -> NA | O6: {=IF(ISBLANK($AQ6), "", INDEX([2]SalmonProps!$A$2:$AA$10001,MATCH(1,($A6=[2]SalmonProps!$A$2:$A$10001)*(1=[2]SalmonProps!$C$2:$C$10001)*(1=[2]SalmonProps!$D$2:$D$10001)*("A2" = [2]SalmonProps!$B$2:$B$10001)*($AP6 = [2]SalmonProps!$F$2:$F$10001) *($AR6 = [2]SalmonProps!$G$2:$G$10001),0), 19))} -> #N/A | P6: {=IF(ISBLANK($AQ6), "", INDEX([2]SalmonProps!$A$2:$AA$10001,MATCH(1,($A6=[2]SalmonProps!$A$2:$A$10001)*(2=[2]SalmonProps!$C$2:$C$10001)*(1=[2]SalmonProps!$D$2:$D$10001)*("A2" = [2]SalmonProps!$B$2:$B$10001)*($AP6 = [2]SalmonProps!$F$2:$F$10001) *($AR6 = [2]SalmonProps!$G$2:$G$10001),0), 19))} -> #N/A | Q6: {=IF(ISBLANK($AQ6), "", INDEX([2]SalmonProps!$A$2:$AA$10001,MATCH(1,($A6=[2]SalmonProps!$A$2:$A$10001)*(3=[2]SalmonProps!$C$2:$C$10001)*(1=[2]SalmonProps!$D$2:$D$10001)*("A2" = [2]SalmonProps!$B$2:$B$10001)*($AP6 = [2]SalmonProps!$F$2:$F$10001) *($AR6 = [2]SalmonProps!$G$2:$G$10001),0), 19))} -> #N/A | R6: {=IF(ISBLANK($AQ6), "", INDEX([2]SalmonProps!$A$2:$AA$10001,MATCH(1,($A6=[2]SalmonProps!$A$2:$A$10001)*(1=[2]SalmonProps!$C$2:$C$10001)*(1=[2]SalmonProps!$D$2:$D$10001)*("A1" = [2]SalmonProps!$B$2:$B$10001)*($AP6 = [2]SalmonProps!$F$2:$F$10001) *($AR6 = [2]SalmonProps!$G$2:$G$10001),0), 18))} -> NA | S6: {=IF(ISBLANK($AQ6), "", INDEX([2]SalmonProps!$A$2:$AA$10001,MATCH(1,($A6=[2]SalmonProps!$A$2:$A$10001)*(1=[2]SalmonProps!$C$2:$C$10001)*(2=[2]SalmonProps!$D$2:$D$10001)*("A1" = [2]SalmonProps!$B$2:$B$10001)*($AP6 = [2]SalmonProps!$F$2:$F$10001) *($AR6 = [2]SalmonProps!$G$2:$G$10001),0), 18))} -> NA | T6: {=IF(ISBLANK($AQ6), "", INDEX([2]SalmonProps!$A$2:$AA$10001,MATCH(1,($A6=[2]SalmonProps!$A$2:$A$10001)*(1=[2]SalmonProps!$C$2:$C$10001)*("1&2"=[2]SalmonProps!$D$2:$D$10001)*("A1" = [2]SalmonProps!$B$2:$B$10001)*($AP6 = [2]SalmonProps!$F$2:$F$10001) *($AR6 = [2]SalmonProps!$G$2:$G$10001),0), 18))} -> NA | U6: {=IF(ISBLANK($AQ6), "", INDEX([2]SalmonProps!$A$2:$AA$10001,MATCH(1,($A6=[2]SalmonProps!$A$2:$A$10001)*(2=[2]SalmonProps!$C$2:$C$10001)*(3=[2]SalmonProps!$D$2:$D$10001)*("A1" = [2]SalmonProps!$B$2:$B$10001)*($AP6 = [2]SalmonProps!$F$2:$F$10001) *($AR6 = [2]SalmonProps!$G$2:$G$10001),0), 18))} -> NA | V6: {=IF(ISBLANK($AQ6), "", INDEX([2]SalmonProps!$A$2:$AA$10001,MATCH(1,($A6=[2]SalmonProps!$A$2:$A$10001)*(3=[2]SalmonProps!$C$2:$C$10001)*(3=[2]SalmonProps!$D$2:$D$10001)*("A1" = [2]SalmonProps!$B$2:$B$10001)*($AP6 = [2]SalmonProps!$F$2:$F$10001) *($AR6 = [2]SalmonProps!$G$2:$G$10001),0), 18))} -> NA | W6: {=IF(ISBLANK($AQ6), "", INDEX([2]SalmonProps!$A$2:$AA$10001,MATCH(1,($A6=[2]SalmonProps!$A$2:$A$10001)*(1=[2]SalmonProps!$C$2:$C$10001)*(1=[2]SalmonProps!$D$2:$D$10001)*("A2" = [2]SalmonProps!$B$2:$B$10001)*($AP6 = [2]SalmonProps!$F$2:$F$10001) *($AR6 = [2]SalmonProps!$G$2:$G$10001),0), 18))} -> #N/A | X6: {=IF(ISBLANK($AQ6), "", INDEX([2]SalmonProps!$A$2:$AA$10001,MATCH(1,($A6=[2]SalmonProps!$A$2:$A$10001)*(2=[2]SalmonProps!$C$2:$C$10001)*(1=[2]SalmonProps!$D$2:$D$10001)*("A2" = [2]SalmonProps!$B$2:$B$10001)*($AP6 = [2]SalmonProps!$F$2:$F$10001) *($AR6 = [2]SalmonProps!$G$2:$G$10001),0), 18))} -> #N/A | Y6: {=IF(ISBLANK($AQ6), "", INDEX([2]SalmonProps!$A$2:$AA$10001,MATCH(1,($A6=[2]SalmonProps!$A$2:$A$10001)*(3=[2]SalmonProps!$C$2:$C$10001)*(1=[2]SalmonProps!$D$2:$D$10001)*("A2" = [2]SalmonProps!$B$2:$B$10001)*($AP6 = [2]SalmonProps!$F$2:$F$10001) *($AR6 = [2]SalmonProps!$G$2:$G$10001),0), 18))} -> #N/A | Z6: {=IF(ISBLANK($AQ6), "", INDEX([2]SalmonProps!$A$2:$AA$10001,MATCH(1,($A6=[2]SalmonProps!$A$2:$A$10001)*(1=[2]SalmonProps!$C$2:$C$10001)*(1=[2]SalmonProps!$D$2:$D$10001)*("A1" = [2]SalmonProps!$B$2:$B$10001)*($AP6 = [2]SalmonProps!$F$2:$F$10001) *($AR6 = [2]SalmonProps!$G$2:$G$10001),0), 15))} -> 0.0603 | AA6: {=IF(ISBLANK($AQ6), "", INDEX([2]SalmonProps!$A$2:$AA$10001,MATCH(1,($A6=[2]SalmonProps!$A$2:$A$10001)*(1=[2]SalmonProps!$C$2:$C$10001)*(2=[2]SalmonProps!$D$2:$D$10001)*("A1" = [2]SalmonProps!$B$2:$B$10001)*($AP6 = [2]SalmonProps!$F$2:$F$10001) *($AR6 = [2]SalmonProps!$G$2:$G$10001),0), 15))} -> 0.0198 | AB6: {=IF(ISBLANK($AQ6), "", INDEX([2]SalmonProps!$A$2:$AA$10001,MATCH(1,($A6=[2]SalmonProps!$A$2:$A$10001)*(1=[2]SalmonProps!$C$2:$C$10001)*("1&2"=[2]SalmonProps!$D$2:$D$10001)*("A1" = [2]SalmonProps!$B$2:$B$10001)*($AP6 = [2]SalmonProps!$F$2:$F$10001) *($AR6 = [2]SalmonProps!$G$2:$G$10001),0), 15))} -> 0.0437 | AC6: {=IF(ISBLANK($AQ6), "", INDEX([2]SalmonProps!$A$2:$AA$10001,MATCH(1,($A6=[2]SalmonProps!$A$2:$A$10001)*(2=[2]SalmonProps!$C$2:$C$10001)*(3=[2]SalmonProps!$D$2:$D$10001)*("A1" = [2]SalmonProps!$B$2:$B$10001)*($AP6 = [2]SalmonProps!$F$2:$F$10001) *($AR6 = [2]SalmonProps!$G$2:$G$10001),0), 15))} -> 0.1587 | AD6: {=IF(ISBLANK($AQ6), "", INDEX([2]SalmonProps!$A$2:$AA$10001,MATCH(1,($A6=[2]SalmonProps!$A$2:$A$10001)*(3=[2]SalmonProps!$C$2:$C$10001)*(3=[2]SalmonProps!$D$2:$D$10001)*("A1" = [2]SalmonProps!$B$2:$B$10001)*($AP6 = [2]SalmonProps!$F$2:$F$10001) *($AR6 = [2]SalmonProps!$G$2:$G$10001),0), 15))} -> 0.1351 | AE6: 0.0639 | AF6: 0.0632 | AG6: 0.2357 | AJ6: {=IF(ISBLANK($AQ6), "", INDEX([2]SalmonProps!$A$2:$AA$10001,MATCH(1,($A6=[2]SalmonProps!$A$2:$A$10001)*($AP6 = [2]SalmonProps!$F$2:$F$10001) *($AR6 = [2]SalmonProps!$G$2:$G$10001),0), 20))} -> 61.4 | AK6: {=IF(ISBLANK($AQ6), "", INDEX([2]SalmonProps!$A$2:$AA$10001,MATCH(1,($A6=[2]SalmonProps!$A$2:$A$10001)*($AP6 = [2]SalmonProps!$F$2:$F$10001) *($AR6 = [2]SalmonProps!$G$2:$G$10001),0), 21))} -> 5 | AL6: {=IF(ISBLANK($AQ6), "", INDEX([2]SalmonProps!$A$2:$AA$10001,MATCH(1,($A6=[2]SalmonProps!$A$2:$A$10001)*($AP6 = [2]SalmonProps!$F$2:$F$10001) *($AR6 = [2]SalmonProps!$G$2:$G$10001),0), 22))} -> 75.1 | AM6: {=IF(ISBLANK($AQ6), "", INDEX([2]SalmonProps!$A$2:$AA$10001,MATCH(1,($A6=[2]SalmonProps!$A$2:$A$10001)*($AP6 = [2]SalmonProps!$F$2:$F$10001) *($AR6 = [2]SalmonProps!$G$2:$G$10001),0), 23))} -> 7.6 | AN6: {=IF(ISBLANK($AQ6), "", INDEX([2]SalmonProps!$A$2:$AA$10001,MATCH(1,($A6=[2]SalmonProps!$A$2:$A$10001)*($AP6 = [2]SalmonProps!$F$2:$F$10001) *($AR6 = [2]SalmonProps!$G$2:$G$10001),0), 26))} -> NA | AO6: {=IF(ISBLANK($AQ6), "", INDEX([2]SalmonProps!$A$2:$AA$10001,MATCH(1,($A6=[2]SalmonProps!$A$2:$A$10001)*($AP6 = [2]SalmonProps!$F$2:$F$10001) *($AR6 = [2]SalmonProps!$G$2:$G$10001),0), 27))} -> NA | AP6: 3 | AQ6: ML - Unweighted | AR6: =INDEX($AT$2:$AU$5, MATCH(AQ6,$AT$2:$AT$5, 0), 2) -> Unweighted
A7: ='[1]Passage Estimates'!$A7 -> 45109 | B7: {=IF(ISBLANK($AQ7), "", INDEX([2]SalmonProps!$A$2:$AA$10001,MATCH(1,($A7=[2]SalmonProps!$A$2:$A$10001)*(1=[2]SalmonProps!$C$2:$C$10001)*(1=[2]SalmonProps!$D$2:$D$10001)*("A1" = [2]SalmonProps!$B$2:$B$10001)*($AP7 = [2]SalmonProps!$F$2:$F$10001) *($AR7 = [2]SalmonProps!$G$2:$G$10001),0), 17))} -> 0 | C7: {=IF(ISBLANK($AQ7), "", INDEX([2]SalmonProps!$A$2:$AA$10001,MATCH(1,($A7=[2]SalmonProps!$A$2:$A$10001)*(1=[2]SalmonProps!$C$2:$C$10001)*(2=[2]SalmonProps!$D$2:$D$10001)*("A1" = [2]SalmonProps!$B$2:$B$10001)*($AP7 = [2]SalmonProps!$F$2:$F$10001) *($AR7 = [2]SalmonProps!$G$2:$G$10001),0), 17))} -> 0 | D7: {=IF(ISBLANK($AQ7), "", INDEX([2]SalmonProps!$A$2:$AA$10001,MATCH(1,($A7=[2]SalmonProps!$A$2:$A$10001)*(1=[2]SalmonProps!$C$2:$C$10001)*("1&2"=[2]SalmonProps!$D$2:$D$10001)*("A1" = [2]SalmonProps!$B$2:$B$10001)*($AP7 = [2]SalmonProps!$F$2:$F$10001) *($AR7 = [2]SalmonProps!$G$2:$G$10001),0), 17))} -> 0 | E7: {=IF(ISBLANK($AQ7), "", INDEX([2]SalmonProps!$A$2:$AA$10001,MATCH(1,($A7=[2]SalmonProps!$A$2:$A$10001)*(2=[2]SalmonProps!$C$2:$C$10001)*(3=[2]SalmonProps!$D$2:$D$10001)*("A1" = [2]SalmonProps!$B$2:$B$10001)*($AP7 = [2]SalmonProps!$F$2:$F$10001) *($AR7 = [2]SalmonProps!$G$2:$G$10001),0), 17))} -> 0.0304 | F7: {=IF(ISBLANK($AQ7), "", INDEX([2]SalmonProps!$A$2:$AA$10001,MATCH(1,($A7=[2]SalmonProps!$A$2:$A$10001)*(3=[2]SalmonProps!$C$2:$C$10001)*(3=[2]SalmonProps!$D$2:$D$10001)*("A1" = [2]SalmonProps!$B$2:$B$10001)*($AP7 = [2]SalmonProps!$F$2:$F$10001) *($AR7 = [2]SalmonProps!$G$2:$G$10001),0), 17))} -> 0.224 | G7: 0 | H7: 0.0333 | I7: 0.0694 | J7: {=IF(ISBLANK($AQ7), "", INDEX([2]SalmonProps!$A$2:$AA$10001,MATCH(1,($A7=[2]SalmonProps!$A$2:$A$10001)*(1=[2]SalmonProps!$C$2:$C$10001)*(1=[2]SalmonProps!$D$2:$D$10001)*("A1" = [2]SalmonProps!$B$2:$B$10001)*($AP7 = [2]SalmonProps!$F$2:$F$10001) *($AR7 = [2]SalmonProps!$G$2:$G$10001),0), 19))} -> NA | K7: {=IF(ISBLANK($AQ7), "", INDEX([2]SalmonProps!$A$2:$AA$10001,MATCH(1,($A7=[2]SalmonProps!$A$2:$A$10001)*(1=[2]SalmonProps!$C$2:$C$10001)*(2=[2]SalmonProps!$D$2:$D$10001)*("A1" = [2]SalmonProps!$B$2:$B$10001)*($AP7 = [2]SalmonProps!$F$2:$F$10001) *($AR7 = [2]SalmonProps!$G$2:$G$10001),0), 19))} -> NA | L7: {=IF(ISBLANK($AQ7), "", INDEX([2]SalmonProps!$A$2:$AA$10001,MATCH(1,($A7=[2]SalmonProps!$A$2:$A$10001)*(1=[2]SalmonProps!$C$2:$C$10001)*("1&2"=[2]SalmonProps!$D$2:$D$10001)*("A1" = [2]SalmonProps!$B$2:$B$10001)*($AP7 = [2]SalmonProps!$F$2:$F$10001) *($AR7 = [2]SalmonProps!$G$2:$G$10001),0), 19))} -> NA | M7: {=IF(ISBLANK($AQ7), "", INDEX([2]SalmonProps!$A$2:$AA$10001,MATCH(1,($A7=[2]SalmonProps!$A$2:$A$10001)*(2=[2]SalmonProps!$C$2:$C$10001)*(3=[2]SalmonProps!$D$2:$D$10001)*("A1" = [2]SalmonProps!$B$2:$B$10001)*($AP7 = [2]SalmonProps!$F$2:$F$10001) *($AR7 = [2]SalmonProps!$G$2:$G$10001),0), 19))} -> NA | N7: {=IF(ISBLANK($AQ7), "", INDEX([2]SalmonProps!$A$2:$AA$10001,MATCH(1,($A7=[2]SalmonProps!$A$2:$A$10001)*(3=[2]SalmonProps!$C$2:$C$10001)*(3=[2]SalmonProps!$D$2:$D$10001)*("A1" = [2]SalmonProps!$B$2:$B$10001)*($AP7 = [2]SalmonProps!$F$2:$F$10001) *($AR7 = [2]SalmonProps!$G$2:$G$10001),0), 19))} -> NA | O7: {=IF(ISBLANK($AQ7), "", INDEX([2]SalmonProps!$A$2:$AA$10001,MATCH(1,($A7=[2]SalmonProps!$A$2:$A$10001)*(1=[2]SalmonProps!$C$2:$C$10001)*(1=[2]SalmonProps!$D$2:$D$10001)*("A2" = [2]SalmonProps!$B$2:$B$10001)*($AP7 = [2]SalmonProps!$F$2:$F$10001) *($AR7 = [2]SalmonProps!$G$2:$G$10001),0), 19))} -> #N/A | P7: {=IF(ISBLANK($AQ7), "", INDEX([2]SalmonProps!$A$2:$AA$10001,MATCH(1,($A7=[2]SalmonProps!$A$2:$A$10001)*(2=[2]SalmonProps!$C$2:$C$10001)*(1=[2]SalmonProps!$D$2:$D$10001)*("A2" = [2]SalmonProps!$B$2:$B$10001)*($AP7 = [2]SalmonProps!$F$2:$F$10001) *($AR7 = [2]SalmonProps!$G$2:$G$10001),0), 19))} -> #N/A | Q7: {=IF(ISBLANK($AQ7), "", INDEX([2]SalmonProps!$A$2:$AA$10001,MATCH(1,($A7=[2]SalmonProps!$A$2:$A$10001)*(3=[2]SalmonProps!$C$2:$C$10001)*(1=[2]SalmonProps!$D$2:$D$10001)*("A2" = [2]SalmonProps!$B$2:$B$10001)*($AP7 = [2]SalmonProps!$F$2:$F$10001) *($AR7 = [2]SalmonProps!$G$2:$G$10001),0), 19))} -> #N/A | R7: {=IF(ISBLANK($AQ7), "", INDEX([2]SalmonProps!$A$2:$AA$10001,MATCH(1,($A7=[2]SalmonProps!$A$2:$A$10001)*(1=[2]SalmonProps!$C$2:$C$10001)*(1=[2]SalmonProps!$D$2:$D$10001)*("A1" = [2]SalmonProps!$B$2:$B$10001)*($AP7 = [2]SalmonProps!$F$2:$F$10001) *($AR7 = [2]SalmonProps!$G$2:$G$10001),0), 18))} -> NA | S7: {=IF(ISBLANK($AQ7), "", INDEX([2]SalmonProps!$A$2:$AA$10001,MATCH(1,($A7=[2]SalmonProps!$A$2:$A$10001)*(1=[2]SalmonProps!$C$2:$C$10001)*(2=[2]SalmonProps!$D$2:$D$10001)*("A1" = [2]SalmonProps!$B$2:$B$10001)*($AP7 = [2]SalmonProps!$F$2:$F$10001) *($AR7 = [2]SalmonProps!$G$2:$G$10001),0), 18))} -> NA | T7: {=IF(ISBLANK($AQ7), "", INDEX([2]SalmonProps!$A$2:$AA$10001,MATCH(1,($A7=[2]SalmonProps!$A$2:$A$10001)*(1=[2]SalmonProps!$C$2:$C$10001)*("1&2"=[2]SalmonProps!$D$2:$D$10001)*("A1" = [2]SalmonProps!$B$2:$B$10001)*($AP7 = [2]SalmonProps!$F$2:$F$10001) *($AR7 = [2]SalmonProps!$G$2:$G$10001),0), 18))} -> NA | U7: {=IF(ISBLANK($AQ7), "", INDEX([2]SalmonProps!$A$2:$AA$10001,MATCH(1,($A7=[2]SalmonProps!$A$2:$A$10001)*(2=[2]SalmonProps!$C$2:$C$10001)*(3=[2]SalmonProps!$D$2:$D$10001)*("A1" = [2]SalmonProps!$B$2:$B$10001)*($AP7 = [2]SalmonProps!$F$2:$F$10001) *($AR7 = [2]SalmonProps!$G$2:$G$10001),0), 18))} -> NA | V7: {=IF(ISBLANK($AQ7), "", INDEX([2]SalmonProps!$A$2:$AA$10001,MATCH(1,($A7=[2]SalmonProps!$A$2:$A$10001)*(3=[2]SalmonProps!$C$2:$C$10001)*(3=[2]SalmonProps!$D$2:$D$10001)*("A1" = [2]SalmonProps!$B$2:$B$10001)*($AP7 = [2]SalmonProps!$F$2:$F$10001) *($AR7 = [2]SalmonProps!$G$2:$G$10001),0), 18))} -> NA | W7: {=IF(ISBLANK($AQ7), "", INDEX([2]SalmonProps!$A$2:$AA$10001,MATCH(1,($A7=[2]SalmonProps!$A$2:$A$10001)*(1=[2]SalmonProps!$C$2:$C$10001)*(1=[2]SalmonProps!$D$2:$D$10001)*("A2" = [2]SalmonProps!$B$2:$B$10001)*($AP7 = [2]SalmonProps!$F$2:$F$10001) *($AR7 = [2]SalmonProps!$G$2:$G$10001),0), 18))} -> #N/A | X7: {=IF(ISBLANK($AQ7), "", INDEX([2]SalmonProps!$A$2:$AA$10001,MATCH(1,($A7=[2]SalmonProps!$A$2:$A$10001)*(2=[2]SalmonProps!$C$2:$C$10001)*(1=[2]SalmonProps!$D$2:$D$10001)*("A2" = [2]SalmonProps!$B$2:$B$10001)*($AP7 = [2]SalmonProps!$F$2:$F$10001) *($AR7 = [2]SalmonProps!$G$2:$G$10001),0), 18))} -> #N/A | Y7: {=IF(ISBLANK($AQ7), "", INDEX([2]SalmonProps!$A$2:$AA$10001,MATCH(1,($A7=[2]SalmonProps!$A$2:$A$10001)*(3=[2]SalmonProps!$C$2:$C$10001)*(1=[2]SalmonProps!$D$2:$D$10001)*("A2" = [2]SalmonProps!$B$2:$B$10001)*($AP7 = [2]SalmonProps!$F$2:$F$10001) *($AR7 = [2]SalmonProps!$G$2:$G$10001),0), 18))} -> #N/A | Z7: {=IF(ISBLANK($AQ7), "", INDEX([2]SalmonProps!$A$2:$AA$10001,MATCH(1,($A7=[2]SalmonProps!$A$2:$A$10001)*(1=[2]SalmonProps!$C$2:$C$10001)*(1=[2]SalmonProps!$D$2:$D$10001)*("A1" = [2]SalmonProps!$B$2:$B$10001)*($AP7 = [2]SalmonProps!$F$2:$F$10001) *($AR7 = [2]SalmonProps!$G$2:$G$10001),0), 15))} -> 0.0761 | AA7: {=IF(ISBLANK($AQ7), "", INDEX([2]SalmonProps!$A$2:$AA$10001,MATCH(1,($A7=[2]SalmonProps!$A$2:$A$10001)*(1=[2]SalmonProps!$C$2:$C$10001)*(2=[2]SalmonProps!$D$2:$D$10001)*("A1" = [2]SalmonProps!$B$2:$B$10001)*($AP7 = [2]SalmonProps!$F$2:$F$10001) *($AR7 = [2]SalmonProps!$G$2:$G$10001),0), 15))} -> 0.0182 | AB7: {=IF(ISBLANK($AQ7), "", INDEX([2]SalmonProps!$A$2:$AA$10001,MATCH(1,($A7=[2]SalmonProps!$A$2:$A$10001)*(1=[2]SalmonProps!$C$2:$C$10001)*("1&2"=[2]SalmonProps!$D$2:$D$10001)*("A1" = [2]SalmonProps!$B$2:$B$10001)*($AP7 = [2]SalmonProps!$F$2:$F$10001) *($AR7 = [2]SalmonProps!$G$2:$G$10001),0), 15))} -> 0.0481 | AC7: {=IF(ISBLANK($AQ7), "", INDEX([2]SalmonProps!$A$2:$AA$10001,MATCH(1,($A7=[2]SalmonProps!$A$2:$A$10001)*(2=[2]SalmonProps!$C$2:$C$10001)*(3=[2]SalmonProps!$D$2:$D$10001)*("A1" = [2]SalmonProps!$B$2:$B$10001)*($AP7 = [2]SalmonProps!$F$2:$F$10001) *($AR7 = [2]SalmonProps!$G$2:$G$10001),0), 15))} -> 0.1587 | AD7: {=IF(ISBLANK($AQ7), "", INDEX([2]SalmonProps!$A$2:$AA$10001,MATCH(1,($A7=[2]SalmonProps!$A$2:$A$10001)*(3=[2]SalmonProps!$C$2:$C$10001)*(3=[2]SalmonProps!$D$2:$D$10001)*("A1" = [2]SalmonProps!$B$2:$B$10001)*($AP7 = [2]SalmonProps!$F$2:$F$10001) *($AR7 = [2]SalmonProps!$G$2:$G$10001),0), 15))} -> 0.3547 | AE7: 0.0639 | AF7: 0.0632 | AG7: 0.2357 | AJ7: {=IF(ISBLANK($AQ7), "", INDEX([2]SalmonProps!$A$2:$AA$10001,MATCH(1,($A7=[2]SalmonProps!$A$2:$A$10001)*($AP7 = [2]SalmonProps!$F$2:$F$10001) *($AR7 = [2]SalmonProps!$G$2:$G$10001),0), 20))} -> 61.4 | AK7: {=IF(ISBLANK($AQ7), "", INDEX([2]SalmonProps!$A$2:$AA$10001,MATCH(1,($A7=[2]SalmonProps!$A$2:$A$10001)*($AP7 = [2]SalmonProps!$F$2:$F$10001) *($AR7 = [2]SalmonProps!$G$2:$G$10001),0), 21))} -> 5 | AL7: {=IF(ISBLANK($AQ7), "", INDEX([2]SalmonProps!$A$2:$AA$10001,MATCH(1,($A7=[2]SalmonProps!$A$2:$A$10001)*($AP7 = [2]SalmonProps!$F$2:$F$10001) *($AR7 = [2]SalmonProps!$G$2:$G$10001),0), 22))} -> 75.1 | AM7: {=IF(ISBLANK($AQ7), "", INDEX([2]SalmonProps!$A$2:$AA$10001,MATCH(1,($A7=[2]SalmonProps!$A$2:$A$10001)*($AP7 = [2]SalmonProps!$F$2:$F$10001) *($AR7 = [2]SalmonProps!$G$2:$G$10001),0), 23))} -> 7.6 | AN7: {=IF(ISBLANK($AQ7), "", INDEX([2]SalmonProps!$A$2:$AA$10001,MATCH(1,($A7=[2]SalmonProps!$A$2:$A$10001)*($AP7 = [2]SalmonProps!$F$2:$F$10001) *($AR7 = [2]SalmonProps!$G$2:$G$10001),0), 26))} -> NA | AO7: {=IF(ISBLANK($AQ7), "", INDEX([2]SalmonProps!$A$2:$AA$10001,MATCH(1,($A7=[2]SalmonProps!$A$2:$A$10001)*($AP7 = [2]SalmonProps!$F$2:$F$10001) *($AR7 = [2]SalmonProps!$G$2:$G$10001),0), 27))} -> NA | AP7: 3 | AQ7: ML - Unweighted | AR7: =INDEX($AT$2:$AU$5, MATCH(AQ7,$AT$2:$AT$5, 0), 2) -> Unweighted
A8: ='[1]Passage Estimates'!$A8 -> 45110 | B8: {=IF(ISBLANK($AQ8), "", INDEX([2]SalmonProps!$A$2:$AA$10001,MATCH(1,($A8=[2]SalmonProps!$A$2:$A$10001)*(1=[2]SalmonProps!$C$2:$C$10001)*(1=[2]SalmonProps!$D$2:$D$10001)*("A1" = [2]SalmonProps!$B$2:$B$10001)*($AP8 = [2]SalmonProps!$F$2:$F$10001) *($AR8 = [2]SalmonProps!$G$2:$G$10001),0), 17))} -> 0.012 | C8: {=IF(ISBLANK($AQ8), "", INDEX([2]SalmonProps!$A$2:$AA$10001,MATCH(1,($A8=[2]SalmonProps!$A$2:$A$10001)*(1=[2]SalmonProps!$C$2:$C$10001)*(2=[2]SalmonProps!$D$2:$D$10001)*("A1" = [2]SalmonProps!$B$2:$B$10001)*($AP8 = [2]SalmonProps!$F$2:$F$10001) *($AR8 = [2]SalmonProps!$G$2:$G$10001),0), 17))} -> 0 | D8: {=IF(ISBLANK($AQ8), "", INDEX([2]SalmonProps!$A$2:$AA$10001,MATCH(1,($A8=[2]SalmonProps!$A$2:$A$10001)*(1=[2]SalmonProps!$C$2:$C$10001)*("1&2"=[2]SalmonProps!$D$2:$D$10001)*("A1" = [2]SalmonProps!$B$2:$B$10001)*($AP8 = [2]SalmonProps!$F$2:$F$10001) *($AR8 = [2]SalmonProps!$G$2:$G$10001),0), 17))} -> 0.0037 | E8: {=IF(ISBLANK($AQ8), "", INDEX([2]SalmonProps!$A$2:$AA$10001,MATCH(1,($A8=[2]SalmonProps!$A$2:$A$10001)*(2=[2]SalmonProps!$C$2:$C$10001)*(3=[2]SalmonProps!$D$2:$D$10001)*("A1" = [2]SalmonProps!$B$2:$B$10001)*($AP8 = [2]SalmonProps!$F$2:$F$10001) *($AR8 = [2]SalmonProps!$G$2:$G$10001),0), 17))} -> 0.0358 | F8: {=IF(ISBLANK($AQ8), "", INDEX([2]SalmonProps!$A$2:$AA$10001,MATCH(1,($A8=[2]SalmonProps!$A$2:$A$10001)*(3=[2]SalmonProps!$C$2:$C$10001)*(3=[2]SalmonProps!$D$2:$D$10001)*("A1" = [2]SalmonProps!$B$2:$B$10001)*($AP8 = [2]SalmonProps!$F$2:$F$10001) *($AR8 = [2]SalmonProps!$G$2:$G$10001),0), 17))} -> 0.2318 | G8: 0 | H8: 0.0333 | I8: 0.0694 | J8: {=IF(ISBLANK($AQ8), "", INDEX([2]SalmonProps!$A$2:$AA$10001,MATCH(1,($A8=[2]SalmonProps!$A$2:$A$10001)*(1=[2]SalmonProps!$C$2:$C$10001)*(1=[2]SalmonProps!$D$2:$D$10001)*("A1" = [2]SalmonProps!$B$2:$B$10001)*($AP8 = [2]SalmonProps!$F$2:$F$10001) *($AR8 = [2]SalmonProps!$G$2:$G$10001),0), 19))} -> NA | K8: {=IF(ISBLANK($AQ8), "", INDEX([2]SalmonProps!$A$2:$AA$10001,MATCH(1,($A8=[2]SalmonProps!$A$2:$A$10001)*(1=[2]SalmonProps!$C$2:$C$10001)*(2=[2]SalmonProps!$D$2:$D$10001)*("A1" = [2]SalmonProps!$B$2:$B$10001)*($AP8 = [2]SalmonProps!$F$2:$F$10001) *($AR8 = [2]SalmonProps!$G$2:$G$10001),0), 19))} -> NA | L8: {=IF(ISBLANK($AQ8), "", INDEX([2]SalmonProps!$A$2:$AA$10001,MATCH(1,($A8=[2]SalmonProps!$A$2:$A$10001)*(1=[2]SalmonProps!$C$2:$C$10001)*("1&2"=[2]SalmonProps!$D$2:$D$10001)*("A1" = [2]SalmonProps!$B$2:$B$10001)*($AP8 = [2]SalmonProps!$F$2:$F$10001) *($AR8 = [2]SalmonProps!$G$2:$G$10001),0), 19))} -> NA | M8: {=IF(ISBLANK($AQ8), "", INDEX([2]SalmonProps!$A$2:$AA$10001,MATCH(1,($A8=[2]SalmonProps!$A$2:$A$10001)*(2=[2]SalmonProps!$C$2:$C$10001)*(3=[2]SalmonProps!$D$2:$D$10001)*("A1" = [2]SalmonProps!$B$2:$B$10001)*($AP8 = [2]SalmonProps!$F$2:$F$10001) *($AR8 = [2]SalmonProps!$G$2:$G$10001),0), 19))} -> NA | N8: {=IF(ISBLANK($AQ8), "", INDEX([2]SalmonProps!$A$2:$AA$10001,MATCH(1,($A8=[2]SalmonProps!$A$2:$A$10001)*(3=[2]SalmonProps!$C$2:$C$10001)*(3=[2]SalmonProps!$D$2:$D$10001)*("A1" = [2]SalmonProps!$B$2:$B$10001)*($AP8 = [2]SalmonProps!$F$2:$F$10001) *($AR8 = [2]SalmonProps!$G$2:$G$10001),0), 19))} -> NA | O8: {=IF(ISBLANK($AQ8), "", INDEX([2]SalmonProps!$A$2:$AA$10001,MATCH(1,($A8=[2]SalmonProps!$A$2:$A$10001)*(1=[2]SalmonProps!$C$2:$C$10001)*(1=[2]SalmonProps!$D$2:$D$10001)*("A2" = [2]SalmonProps!$B$2:$B$10001)*($AP8 = [2]SalmonProps!$F$2:$F$10001) *($AR8 = [2]SalmonProps!$G$2:$G$10001),0), 19))} -> #N/A | P8: {=IF(ISBLANK($AQ8), "", INDEX([2]SalmonProps!$A$2:$AA$10001,MATCH(1,($A8=[2]SalmonProps!$A$2:$A$10001)*(2=[2]SalmonProps!$C$2:$C$10001)*(1=[2]SalmonProps!$D$2:$D$10001)*("A2" = [2]SalmonProps!$B$2:$B$10001)*($AP8 = [2]SalmonProps!$F$2:$F$10001) *($AR8 = [2]SalmonProps!$G$2:$G$10001),0), 19))} -> #N/A | Q8: {=IF(ISBLANK($AQ8), "", INDEX([2]SalmonProps!$A$2:$AA$10001,MATCH(1,($A8=[2]SalmonProps!$A$2:$A$10001)*(3=[2]SalmonProps!$C$2:$C$10001)*(1=[2]SalmonProps!$D$2:$D$10001)*("A2" = [2]SalmonProps!$B$2:$B$10001)*($AP8 = [2]SalmonProps!$F$2:$F$10001) *($AR8 = [2]SalmonProps!$G$2:$G$10001),0), 19))} -> #N/A | R8: {=IF(ISBLANK($AQ8), "", INDEX([2]SalmonProps!$A$2:$AA$10001,MATCH(1,($A8=[2]SalmonProps!$A$2:$A$10001)*(1=[2]SalmonProps!$C$2:$C$10001)*(1=[2]SalmonProps!$D$2:$D$10001)*("A1" = [2]SalmonProps!$B$2:$B$10001)*($AP8 = [2]SalmonProps!$F$2:$F$10001) *($AR8 = [2]SalmonProps!$G$2:$G$10001),0), 18))} -> NA | S8: {=IF(ISBLANK($AQ8), "", INDEX([2]SalmonProps!$A$2:$AA$10001,MATCH(1,($A8=[2]SalmonProps!$A$2:$A$10001)*(1=[2]SalmonProps!$C$2:$C$10001)*(2=[2]SalmonProps!$D$2:$D$10001)*("A1" = [2]SalmonProps!$B$2:$B$10001)*($AP8 = [2]SalmonProps!$F$2:$F$10001) *($AR8 = [2]SalmonProps!$G$2:$G$10001),0), 18))} -> NA | T8: {=IF(ISBLANK($AQ8), "", INDEX([2]SalmonProps!$A$2:$AA$10001,MATCH(1,($A8=[2]SalmonProps!$A$2:$A$10001)*(1=[2]SalmonProps!$C$2:$C$10001)*("1&2"=[2]SalmonProps!$D$2:$D$10001)*("A1" = [2]SalmonProps!$B$2:$B$10001)*($AP8 = [2]SalmonProps!$F$2:$F$10001) *($AR8 = [2]SalmonProps!$G$2:$G$10001),0), 18))} -> NA | U8: {=IF(ISBLANK($AQ8), "", INDEX([2]SalmonProps!$A$2:$AA$10001,MATCH(1,($A8=[2]SalmonProps!$A$2:$A$10001)*(2=[2]SalmonProps!$C$2:$C$10001)*(3=[2]SalmonProps!$D$2:$D$10001)*("A1" = [2]SalmonProps!$B$2:$B$10001)*($AP8 = [2]SalmonProps!$F$2:$F$10001) *($AR8 = [2]SalmonProps!$G$2:$G$10001),0), 18))} -> NA | V8: {=IF(ISBLANK($AQ8), "", INDEX([2]SalmonProps!$A$2:$AA$10001,MATCH(1,($A8=[2]SalmonProps!$A$2:$A$10001)*(3=[2]SalmonProps!$C$2:$C$10001)*(3=[2]SalmonProps!$D$2:$D$10001)*("A1" = [2]SalmonProps!$B$2:$B$10001)*($AP8 = [2]SalmonProps!$F$2:$F$10001) *($AR8 = [2]SalmonProps!$G$2:$G$10001),0), 18))} -> NA | W8: {=IF(ISBLANK($AQ8), "", INDEX([2]SalmonProps!$A$2:$AA$10001,MATCH(1,($A8=[2]SalmonProps!$A$2:$A$10001)*(1=[2]SalmonProps!$C$2:$C$10001)*(1=[2]SalmonProps!$D$2:$D$10001)*("A2" = [2]SalmonProps!$B$2:$B$10001)*($AP8 = [2]SalmonProps!$F$2:$F$10001) *($AR8 = [2]SalmonProps!$G$2:$G$10001),0), 18))} -> #N/A | X8: {=IF(ISBLANK($AQ8), "", INDEX([2]SalmonProps!$A$2:$AA$10001,MATCH(1,($A8=[2]SalmonProps!$A$2:$A$10001)*(2=[2]SalmonProps!$C$2:$C$10001)*(1=[2]SalmonProps!$D$2:$D$10001)*("A2" = [2]SalmonProps!$B$2:$B$10001)*($AP8 = [2]SalmonProps!$F$2:$F$10001) *($AR8 = [2]SalmonProps!$G$2:$G$10001),0), 18))} -> #N/A | Y8: {=IF(ISBLANK($AQ8), "", INDEX([2]SalmonProps!$A$2:$AA$10001,MATCH(1,($A8=[2]SalmonProps!$A$2:$A$10001)*(3=[2]SalmonProps!$C$2:$C$10001)*(1=[2]SalmonProps!$D$2:$D$10001)*("A2" = [2]SalmonProps!$B$2:$B$10001)*($AP8 = [2]SalmonProps!$F$2:$F$10001) *($AR8 = [2]SalmonProps!$G$2:$G$10001),0), 18))} -> #N/A | Z8: {=IF(ISBLANK($AQ8), "", INDEX([2]SalmonProps!$A$2:$AA$10001,MATCH(1,($A8=[2]SalmonProps!$A$2:$A$10001)*(1=[2]SalmonProps!$C$2:$C$10001)*(1=[2]SalmonProps!$D$2:$D$10001)*("A1" = [2]SalmonProps!$B$2:$B$10001)*($AP8 = [2]SalmonProps!$F$2:$F$10001) *($AR8 = [2]SalmonProps!$G$2:$G$10001),0), 15))} -> 0.012 | AA8: {=IF(ISBLANK($AQ8), "", INDEX([2]SalmonProps!$A$2:$AA$10001,MATCH(1,($A8=[2]SalmonProps!$A$2:$A$10001)*(1=[2]SalmonProps!$C$2:$C$10001)*(2=[2]SalmonProps!$D$2:$D$10001)*("A1" = [2]SalmonProps!$B$2:$B$10001)*($AP8 = [2]SalmonProps!$F$2:$F$10001) *($AR8 = [2]SalmonProps!$G$2:$G$10001),0), 15))} -> 0.0072 | AB8: {=IF(ISBLANK($AQ8), "", INDEX([2]SalmonProps!$A$2:$AA$10001,MATCH(1,($A8=[2]SalmonProps!$A$2:$A$10001)*(1=[2]SalmonProps!$C$2:$C$10001)*("1&2"=[2]SalmonProps!$D$2:$D$10001)*("A1" = [2]SalmonProps!$B$2:$B$10001)*($AP8 = [2]SalmonProps!$F$2:$F$10001) *($AR8 = [2]SalmonProps!$G$2:$G$10001),0), 15))} -> 0.0075 | AC8: {=IF(ISBLANK($AQ8), "", INDEX([2]SalmonProps!$A$2:$AA$10001,MATCH(1,($A8=[2]SalmonProps!$A$2:$A$10001)*(2=[2]SalmonProps!$C$2:$C$10001)*(3=[2]SalmonProps!$D$2:$D$10001)*("A1" = [2]SalmonProps!$B$2:$B$10001)*($AP8 = [2]SalmonProps!$F$2:$F$10001) *($AR8 = [2]SalmonProps!$G$2:$G$10001),0), 15))} -> 0.1132 | AD8: {=IF(ISBLANK($AQ8), "", INDEX([2]SalmonProps!$A$2:$AA$10001,MATCH(1,($A8=[2]SalmonProps!$A$2:$A$10001)*(3=[2]SalmonProps!$C$2:$C$10001)*(3=[2]SalmonProps!$D$2:$D$10001)*("A1" = [2]SalmonProps!$B$2:$B$10001)*($AP8 = [2]SalmonProps!$F$2:$F$10001) *($AR8 = [2]SalmonProps!$G$2:$G$10001),0), 15))} -> 0.2794 | AE8: 0.0639 | AF8: 0.0632 | AG8: 0.2357 | AJ8: {=IF(ISBLANK($AQ8), "", INDEX([2]SalmonProps!$A$2:$AA$10001,MATCH(1,($A8=[2]SalmonProps!$A$2:$A$10001)*($AP8 = [2]SalmonProps!$F$2:$F$10001) *($AR8 = [2]SalmonProps!$G$2:$G$10001),0), 20))} -> 61.4 | AK8: {=IF(ISBLANK($AQ8), "", INDEX([2]SalmonProps!$A$2:$AA$10001,MATCH(1,($A8=[2]SalmonProps!$A$2:$A$10001)*($AP8 = [2]SalmonProps!$F$2:$F$10001) *($AR8 = [2]SalmonProps!$G$2:$G$10001),0), 21))} -> 5 | AL8: {=IF(ISBLANK($AQ8), "", INDEX([2]SalmonProps!$A$2:$AA$10001,MATCH(1,($A8=[2]SalmonProps!$A$2:$A$10001)*($AP8 = [2]SalmonProps!$F$2:$F$10001) *($AR8 = [2]SalmonProps!$G$2:$G$10001),0), 22))} -> 75.1 | AM8: {=IF(ISBLANK($AQ8), "", INDEX([2]SalmonProps!$A$2:$AA$10001,MATCH(1,($A8=[2]SalmonProps!$A$2:$A$10001)*($AP8 = [2]SalmonProps!$F$2:$F$10001) *($AR8 = [2]SalmonProps!$G$2:$G$10001),0), 23))} -> 7.6 | AN8: {=IF(ISBLANK($AQ8), "", INDEX([2]SalmonProps!$A$2:$AA$10001,MATCH(1,($A8=[2]SalmonProps!$A$2:$A$10001)*($AP8 = [2]SalmonProps!$F$2:$F$10001) *($AR8 = [2]SalmonProps!$G$2:$G$10001),0), 26))} -> NA | AO8: {=IF(ISBLANK($AQ8), "", INDEX([2]SalmonProps!$A$2:$AA$10001,MATCH(1,($A8=[2]SalmonProps!$A$2:$A$10001)*($AP8 = [2]SalmonProps!$F$2:$F$10001) *($AR8 = [2]SalmonProps!$G$2:$G$10001),0), 27))} -> NA | AP8: 3 | AQ8: ML - Unweighted | AR8: =INDEX($AT$2:$AU$5, MATCH(AQ8,$AT$2:$AT$5, 0), 2) -> Unweighted
A9: ='[1]Passage Estimates'!$A9 -> 45111 | B9: {=IF(ISBLANK($AQ9), "", INDEX([2]SalmonProps!$A$2:$AA$10001,MATCH(1,($A9=[2]SalmonProps!$A$2:$A$10001)*(1=[2]SalmonProps!$C$2:$C$10001)*(1=[2]SalmonProps!$D$2:$D$10001)*("A1" = [2]SalmonProps!$B$2:$B$10001)*($AP9 = [2]SalmonProps!$F$2:$F$10001) *($AR9 = [2]SalmonProps!$G$2:$G$10001),0), 17))} -> 0 | C9: {=IF(ISBLANK($AQ9), "", INDEX([2]SalmonProps!$A$2:$AA$10001,MATCH(1,($A9=[2]SalmonProps!$A$2:$A$10001)*(1=[2]SalmonProps!$C$2:$C$10001)*(2=[2]SalmonProps!$D$2:$D$10001)*("A1" = [2]SalmonProps!$B$2:$B$10001)*($AP9 = [2]SalmonProps!$F$2:$F$10001) *($AR9 = [2]SalmonProps!$G$2:$G$10001),0), 17))} -> 0 | D9: {=IF(ISBLANK($AQ9), "", INDEX([2]SalmonProps!$A$2:$AA$10001,MATCH(1,($A9=[2]SalmonProps!$A$2:$A$10001)*(1=[2]SalmonProps!$C$2:$C$10001)*("1&2"=[2]SalmonProps!$D$2:$D$10001)*("A1" = [2]SalmonProps!$B$2:$B$10001)*($AP9 = [2]SalmonProps!$F$2:$F$10001) *($AR9 = [2]SalmonProps!$G$2:$G$10001),0), 17))} -> 0 | E9: {=IF(ISBLANK($AQ9), "", INDEX([2]SalmonProps!$A$2:$AA$10001,MATCH(1,($A9=[2]SalmonProps!$A$2:$A$10001)*(2=[2]SalmonProps!$C$2:$C$10001)*(3=[2]SalmonProps!$D$2:$D$10001)*("A1" = [2]SalmonProps!$B$2:$B$10001)*($AP9 = [2]SalmonProps!$F$2:$F$10001) *($AR9 = [2]SalmonProps!$G$2:$G$10001),0), 17))} -> 0.1421 | F9: {=IF(ISBLANK($AQ9), "", INDEX([2]SalmonProps!$A$2:$AA$10001,MATCH(1,($A9=[2]SalmonProps!$A$2:$A$10001)*(3=[2]SalmonProps!$C$2:$C$10001)*(3=[2]SalmonProps!$D$2:$D$10001)*("A1" = [2]SalmonProps!$B$2:$B$10001)*($AP9 = [2]SalmonProps!$F$2:$F$10001) *($AR9 = [2]SalmonProps!$G$2:$G$10001),0), 17))} -> 0.305 | G9: 0 | H9: 0.0333 | I9: 0.0694 | J9: {=IF(ISBLANK($AQ9), "", INDEX([2]SalmonProps!$A$2:$AA$10001,MATCH(1,($A9=[2]SalmonProps!$A$2:$A$10001)*(1=[2]SalmonProps!$C$2:$C$10001)*(1=[2]SalmonProps!$D$2:$D$10001)*("A1" = [2]SalmonProps!$B$2:$B$10001)*($AP9 = [2]SalmonProps!$F$2:$F$10001) *($AR9 = [2]SalmonProps!$G$2:$G$10001),0), 19))} -> NA | K9: {=IF(ISBLANK($AQ9), "", INDEX([2]SalmonProps!$A$2:$AA$10001,MATCH(1,($A9=[2]SalmonProps!$A$2:$A$10001)*(1=[2]SalmonProps!$C$2:$C$10001)*(2=[2]SalmonProps!$D$2:$D$10001)*("A1" = [2]SalmonProps!$B$2:$B$10001)*($AP9 = [2]SalmonProps!$F$2:$F$10001) *($AR9 = [2]SalmonProps!$G$2:$G$10001),0), 19))} -> NA | L9: {=IF(ISBLANK($AQ9), "", INDEX([2]SalmonProps!$A$2:$AA$10001,MATCH(1,($A9=[2]SalmonProps!$A$2:$A$10001)*(1=[2]SalmonProps!$C$2:$C$10001)*("1&2"=[2]SalmonProps!$D$2:$D$10001)*("A1" = [2]SalmonProps!$B$2:$B$10001)*($AP9 = [2]SalmonProps!$F$2:$F$10001) *($AR9 = [2]SalmonProps!$G$2:$G$10001),0), 19))} -> NA | M9: {=IF(ISBLANK($AQ9), "", INDEX([2]SalmonProps!$A$2:$AA$10001,MATCH(1,($A9=[2]SalmonProps!$A$2:$A$10001)*(2=[2]SalmonProps!$C$2:$C$10001)*(3=[2]SalmonProps!$D$2:$D$10001)*("A1" = [2]SalmonProps!$B$2:$B$10001)*($AP9 = [2]SalmonProps!$F$2:$F$10001) *($AR9 = [2]SalmonProps!$G$2:$G$10001),0), 19))} -> NA | N9: {=IF(ISBLANK($AQ9), "", INDEX([2]SalmonProps!$A$2:$AA$10001,MATCH(1,($A9=[2]SalmonProps!$A$2:$A$10001)*(3=[2]SalmonProps!$C$2:$C$10001)*(3=[2]SalmonProps!$D$2:$D$10001)*("A1" = [2]SalmonProps!$B$2:$B$10001)*($AP9 = [2]SalmonProps!$F$2:$F$10001) *($AR9 = [2]SalmonProps!$G$2:$G$10001),0), 19))} -> NA | O9: {=IF(ISBLANK($AQ9), "", INDEX([2]SalmonProps!$A$2:$AA$10001,MATCH(1,($A9=[2]SalmonProps!$A$2:$A$10001)*(1=[2]SalmonProps!$C$2:$C$10001)*(1=[2]SalmonProps!$D$2:$D$10001)*("A2" = [2]SalmonProps!$B$2:$B$10001)*($AP9 = [2]SalmonProps!$F$2:$F$10001) *($AR9 = [2]SalmonProps!$G$2:$G$10001),0), 19))} -> #N/A | P9: {=IF(ISBLANK($AQ9), "", INDEX([2]SalmonProps!$A$2:$AA$10001,MATCH(1,($A9=[2]SalmonProps!$A$2:$A$10001)*(2=[2]SalmonProps!$C$2:$C$10001)*(1=[2]SalmonProps!$D$2:$D$10001)*("A2" = [2]SalmonProps!$B$2:$B$10001)*($AP9 = [2]SalmonProps!$F$2:$F$10001) *($AR9 = [2]SalmonProps!$G$2:$G$10001),0), 19))} -> #N/A | Q9: {=IF(ISBLANK($AQ9), "", INDEX([2]SalmonProps!$A$2:$AA$10001,MATCH(1,($A9=[2]SalmonProps!$A$2:$A$10001)*(3=[2]SalmonProps!$C$2:$C$10001)*(1=[2]SalmonProps!$D$2:$D$10001)*("A2" = [2]SalmonProps!$B$2:$B$10001)*($AP9 = [2]SalmonProps!$F$2:$F$10001) *($AR9 = [2]SalmonProps!$G$2:$G$10001),0), 19))} -> #N/A | R9: {=IF(ISBLANK($AQ9), "", INDEX([2]SalmonProps!$A$2:$AA$10001,MATCH(1,($A9=[2]SalmonProps!$A$2:$A$10001)*(1=[2]SalmonProps!$C$2:$C$10001)*(1=[2]SalmonProps!$D$2:$D$10001)*("A1" = [2]SalmonProps!$B$2:$B$10001)*($AP9 = [2]SalmonProps!$F$2:$F$10001) *($AR9 = [2]SalmonProps!$G$2:$G$10001),0), 18))} -> NA | S9: {=IF(ISBLANK($AQ9), "", INDEX([2]SalmonProps!$A$2:$AA$10001,MATCH(1,($A9=[2]SalmonProps!$A$2:$A$10001)*(1=[2]SalmonProps!$C$2:$C$10001)*(2=[2]SalmonProps!$D$2:$D$10001)*("A1" = [2]SalmonProps!$B$2:$B$10001)*($AP9 = [2]SalmonProps!$F$2:$F$10001) *($AR9 = [2]SalmonProps!$G$2:$G$10001),0), 18))} -> NA | T9: {=IF(ISBLANK($AQ9), "", INDEX([2]SalmonProps!$A$2:$AA$10001,MATCH(1,($A9=[2]SalmonProps!$A$2:$A$10001)*(1=[2]SalmonProps!$C$2:$C$10001)*("1&2"=[2]SalmonProps!$D$2:$D$10001)*("A1" = [2]SalmonProps!$B$2:$B$10001)*($AP9 = [2]SalmonProps!$F$2:$F$10001) *($AR9 = [2]SalmonProps!$G$2:$G$10001),0), 18))} -> NA | U9: {=IF(ISBLANK($AQ9), "", INDEX([2]SalmonProps!$A$2:$AA$10001,MATCH(1,($A9=[2]SalmonProps!$A$2:$A$10001)*(2=[2]SalmonProps!$C$2:$C$10001)*(3=[2]SalmonProps!$D$2:$D$10001)*("A1" = [2]SalmonProps!$B$2:$B$10001)*($AP9 = [2]SalmonProps!$F$2:$F$10001) *($AR9 = [2]SalmonProps!$G$2:$G$10001),0), 18))} -> NA | V9: {=IF(ISBLANK($AQ9), "", INDEX([2]SalmonProps!$A$2:$AA$10001,MATCH(1,($A9=[2]SalmonProps!$A$2:$A$10001)*(3=[2]SalmonProps!$C$2:$C$10001)*(3=[2]SalmonProps!$D$2:$D$10001)*("A1" = [2]SalmonProps!$B$2:$B$10001)*($AP9 = [2]SalmonProps!$F$2:$F$10001) *($AR9 = [2]SalmonProps!$G$2:$G$10001),0), 18))} -> NA | W9: {=IF(ISBLANK($AQ9), "", INDEX([2]SalmonProps!$A$2:$AA$10001,MATCH(1,($A9=[2]SalmonProps!$A$2:$A$10001)*(1=[2]SalmonProps!$C$2:$C$10001)*(1=[2]SalmonProps!$D$2:$D$10001)*("A2" = [2]SalmonProps!$B$2:$B$10001)*($AP9 = [2]SalmonProps!$F$2:$F$10001) *($AR9 = [2]SalmonProps!$G$2:$G$10001),0), 18))} -> #N/A | X9: {=IF(ISBLANK($AQ9), "", INDEX([2]SalmonProps!$A$2:$AA$10001,MATCH(1,($A9=[2]SalmonProps!$A$2:$A$10001)*(2=[2]SalmonProps!$C$2:$C$10001)*(1=[2]SalmonProps!$D$2:$D$10001)*("A2" = [2]SalmonProps!$B$2:$B$10001)*($AP9 = [2]SalmonProps!$F$2:$F$10001) *($AR9 = [2]SalmonProps!$G$2:$G$10001),0), 18))} -> #N/A | Y9: {=IF(ISBLANK($AQ9), "", INDEX([2]SalmonProps!$A$2:$AA$10001,MATCH(1,($A9=[2]SalmonProps!$A$2:$A$10001)*(3=[2]SalmonProps!$C$2:$C$10001)*(1=[2]SalmonProps!$D$2:$D$10001)*("A2" = [2]SalmonProps!$B$2:$B$10001)*($AP9 = [2]SalmonProps!$F$2:$F$10001) *($AR9 = [2]SalmonProps!$G$2:$G$10001),0), 18))} -> #N/A | Z9: {=IF(ISBLANK($AQ9), "", INDEX([2]SalmonProps!$A$2:$AA$10001,MATCH(1,($A9=[2]SalmonProps!$A$2:$A$10001)*(1=[2]SalmonProps!$C$2:$C$10001)*(1=[2]SalmonProps!$D$2:$D$10001)*("A1" = [2]SalmonProps!$B$2:$B$10001)*($AP9 = [2]SalmonProps!$F$2:$F$10001) *($AR9 = [2]SalmonProps!$G$2:$G$10001),0), 15))} -> 0.0411 | AA9: {=IF(ISBLANK($AQ9), "", INDEX([2]SalmonProps!$A$2:$AA$10001,MATCH(1,($A9=[2]SalmonProps!$A$2:$A$10001)*(1=[2]SalmonProps!$C$2:$C$10001)*(2=[2]SalmonProps!$D$2:$D$10001)*("A1" = [2]SalmonProps!$B$2:$B$10001)*($AP9 = [2]SalmonProps!$F$2:$F$10001) *($AR9 = [2]SalmonProps!$G$2:$G$10001),0), 15))} -> 0.0399 | AB9: {=IF(ISBLANK($AQ9), "", INDEX([2]SalmonProps!$A$2:$AA$10001,MATCH(1,($A9=[2]SalmonProps!$A$2:$A$10001)*(1=[2]SalmonProps!$C$2:$C$10001)*("1&2"=[2]SalmonProps!$D$2:$D$10001)*("A1" = [2]SalmonProps!$B$2:$B$10001)*($AP9 = [2]SalmonProps!$F$2:$F$10001) *($AR9 = [2]SalmonProps!$G$2:$G$10001),0), 15))} -> 0.0407 | AC9: {=IF(ISBLANK($AQ9), "", INDEX([2]SalmonProps!$A$2:$AA$10001,MATCH(1,($A9=[2]SalmonProps!$A$2:$A$10001)*(2=[2]SalmonProps!$C$2:$C$10001)*(3=[2]SalmonProps!$D$2:$D$10001)*("A1" = [2]SalmonProps!$B$2:$B$10001)*($AP9 = [2]SalmonProps!$F$2:$F$10001) *($AR9 = [2]SalmonProps!$G$2:$G$10001),0), 15))} -> 0.2563 | AD9: {=IF(ISBLANK($AQ9), "", INDEX([2]SalmonProps!$A$2:$AA$10001,MATCH(1,($A9=[2]SalmonProps!$A$2:$A$10001)*(3=[2]SalmonProps!$C$2:$C$10001)*(3=[2]SalmonProps!$D$2:$D$10001)*("A1" = [2]SalmonProps!$B$2:$B$10001)*($AP9 = [2]SalmonProps!$F$2:$F$10001) *($AR9 = [2]SalmonProps!$G$2:$G$10001),0), 15))} -> 0.4804 | AE9: 0.0639 | AF9: 0.0632 | AG9: 0.2357 | AH9: {=IF(ISBLANK($AQ9), "", INDEX([2]SalmonProps!$A$2:$AA$10001,MATCH(1,($A9=[2]SalmonProps!$A$2:$A$10001)*($AP9 = [2]SalmonProps!$F$2:$F$10001) *($AR9 = [2]SalmonProps!$G$2:$G$10001),0), 24))} -> NA | AI9: {=IF(ISBLANK($AQ9), "", INDEX([2]SalmonProps!$A$2:$AA$10001,MATCH(1,($A9=[2]SalmonProps!$A$2:$A$10001)*($AP9 = [2]SalmonProps!$F$2:$F$10001) *($AR9 = [2]SalmonProps!$G$2:$G$10001),0), 25))} -> NA | AJ9: {=IF(ISBLANK($AQ9), "", INDEX([2]SalmonProps!$A$2:$AA$10001,MATCH(1,($A9=[2]SalmonProps!$A$2:$A$10001)*($AP9 = [2]SalmonProps!$F$2:$F$10001) *($AR9 = [2]SalmonProps!$G$2:$G$10001),0), 20))} -> 61.4 | AK9: {=IF(ISBLANK($AQ9), "", INDEX([2]SalmonProps!$A$2:$AA$10001,MATCH(1,($A9=[2]SalmonProps!$A$2:$A$10001)*($AP9 = [2]SalmonProps!$F$2:$F$10001) *($AR9 = [2]SalmonProps!$G$2:$G$10001),0), 21))} -> 5 | AL9: {=IF(ISBLANK($AQ9), "", INDEX([2]SalmonProps!$A$2:$AA$10001,MATCH(1,($A9=[2]SalmonProps!$A$2:$A$10001)*($AP9 = [2]SalmonProps!$F$2:$F$10001) *($AR9 = [2]SalmonProps!$G$2:$G$10001),0), 22))} -> 75.1 | AM9: {=IF(ISBLANK($AQ9), "", INDEX([2]SalmonProps!$A$2:$AA$10001,MATCH(1,($A9=[2]SalmonProps!$A$2:$A$10001)*($AP9 = [2]SalmonProps!$F$2:$F$10001) *($AR9 = [2]SalmonProps!$G$2:$G$10001),0), 23))} -> 7.6 | AN9: {=IF(ISBLANK($AQ9), "", INDEX([2]SalmonProps!$A$2:$AA$10001,MATCH(1,($A9=[2]SalmonProps!$A$2:$A$10001)*($AP9 = [2]SalmonProps!$F$2:$F$10001) *($AR9 = [2]SalmonProps!$G$2:$G$10001),0), 26))} -> NA | AO9: {=IF(ISBLANK($AQ9), "", INDEX([2]SalmonProps!$A$2:$AA$10001,MATCH(1,($A9=[2]SalmonProps!$A$2:$A$10001)*($AP9 = [2]SalmonProps!$F$2:$F$10001) *($AR9 = [2]SalmonProps!$G$2:$G$10001),0), 27))} -> NA | AP9: 3 | AQ9: ML - Unweighted | AR9: =INDEX($AT$2:$AU$5, MATCH(AQ9,$AT$2:$AT$5, 0), 2) -> Unweighted
A10: ='[1]Passage Estimates'!$A10 -> 45112 | B10: {=IF(ISBLANK($AQ10), "", INDEX([2]SalmonProps!$A$2:$AA$10001,MATCH(1,($A10=[2]SalmonProps!$A$2:$A$10001)*(1=[2]SalmonProps!$C$2:$C$10001)*(1=[2]SalmonProps!$D$2:$D$10001)*("A1" = [2]SalmonProps!$B$2:$B$10001)*($AP10 = [2]SalmonProps!$F$2:$F$10001) *($AR10 = [2]SalmonProps!$G$2:$G$10001),0), 17))} -> 0 | C10: {=IF(ISBLANK($AQ10), "", INDEX([2]SalmonProps!$A$2:$AA$10001,MATCH(1,($A10=[2]SalmonProps!$A$2:$A$10001)*(1=[2]SalmonProps!$C$2:$C$10001)*(2=[2]SalmonProps!$D$2:$D$10001)*("A1" = [2]SalmonProps!$B$2:$B$10001)*($AP10 = [2]SalmonProps!$F$2:$F$10001) *($AR10 = [2]SalmonProps!$G$2:$G$10001),0), 17))} -> 0 | D10: {=IF(ISBLANK($AQ10), "", INDEX([2]SalmonProps!$A$2:$AA$10001,MATCH(1,($A10=[2]SalmonProps!$A$2:$A$10001)*(1=[2]SalmonProps!$C$2:$C$10001)*("1&2"=[2]SalmonProps!$D$2:$D$10001)*("A1" = [2]SalmonProps!$B$2:$B$10001)*($AP10 = [2]SalmonProps!$F$2:$F$10001) *($AR10 = [2]SalmonProps!$G$2:$G$10001),0), 17))} -> 0 | E10: {=IF(ISBLANK($AQ10), "", INDEX([2]SalmonProps!$A$2:$AA$10001,MATCH(1,($A10=[2]SalmonProps!$A$2:$A$10001)*(2=[2]SalmonProps!$C$2:$C$10001)*(3=[2]SalmonProps!$D$2:$D$10001)*("A1" = [2]SalmonProps!$B$2:$B$10001)*($AP10 = [2]SalmonProps!$F$2:$F$10001) *($AR10 = [2]SalmonProps!$G$2:$G$10001),0), 17))} -> 0.0695 | F10: {=IF(ISBLANK($AQ10), "", INDEX([2]SalmonProps!$A$2:$AA$10001,MATCH(1,($A10=[2]SalmonProps!$A$2:$A$10001)*(3=[2]SalmonProps!$C$2:$C$10001)*(3=[2]SalmonProps!$D$2:$D$10001)*("A1" = [2]SalmonProps!$B$2:$B$10001)*($AP10 = [2]SalmonProps!$F$2:$F$10001) *($AR10 = [2]SalmonProps!$G$2:$G$10001),0), 17))} -> 0.4004 | G10: 0 | H10: 0.0333 | I10: 0.0694 | J10: {=IF(ISBLANK($AQ10), "", INDEX([2]SalmonProps!$A$2:$AA$10001,MATCH(1,($A10=[2]SalmonProps!$A$2:$A$10001)*(1=[2]SalmonProps!$C$2:$C$10001)*(1=[2]SalmonProps!$D$2:$D$10001)*("A1" = [2]SalmonProps!$B$2:$B$10001)*($AP10 = [2]SalmonProps!$F$2:$F$10001) *($AR10 = [2]SalmonProps!$G$2:$G$10001),0), 19))} -> NA | K10: {=IF(ISBLANK($AQ10), "", INDEX([2]SalmonProps!$A$2:$AA$10001,MATCH(1,($A10=[2]SalmonProps!$A$2:$A$10001)*(1=[2]SalmonProps!$C$2:$C$10001)*(2=[2]SalmonProps!$D$2:$D$10001)*("A1" = [2]SalmonProps!$B$2:$B$10001)*($AP10 = [2]SalmonProps!$F$2:$F$10001) *($AR10 = [2]SalmonProps!$G$2:$G$10001),0), 19))} -> NA | L10: {=IF(ISBLANK($AQ10), "", INDEX([2]SalmonProps!$A$2:$AA$10001,MATCH(1,($A10=[2]SalmonProps!$A$2:$A$10001)*(1=[2]SalmonProps!$C$2:$C$10001)*("1&2"=[2]SalmonProps!$D$2:$D$10001)*("A1" = [2]SalmonProps!$B$2:$B$10001)*($AP10 = [2]SalmonProps!$F$2:$F$10001) *($AR10 = [2]SalmonProps!$G$2:$G$10001),0), 19))} -> NA | M10: {=IF(ISBLANK($AQ10), "", INDEX([2]SalmonProps!$A$2:$AA$10001,MATCH(1,($A10=[2]SalmonProps!$A$2:$A$10001)*(2=[2]SalmonProps!$C$2:$C$10001)*(3=[2]SalmonProps!$D$2:$D$10001)*("A1" = [2]SalmonProps!$B$2:$B$10001)*($AP10 = [2]SalmonProps!$F$2:$F$10001) *($AR10 = [2]SalmonProps!$G$2:$G$10001),0), 19))} -> NA | N10: {=IF(ISBLANK($AQ10), "", INDEX([2]SalmonProps!$A$2:$AA$10001,MATCH(1,($A10=[2]SalmonProps!$A$2:$A$10001)*(3=[2]SalmonProps!$C$2:$C$10001)*(3=[2]SalmonProps!$D$2:$D$10001)*("A1" = [2]SalmonProps!$B$2:$B$10001)*($AP10 = [2]SalmonProps!$F$2:$F$10001) *($AR10 = [2]SalmonProps!$G$2:$G$10001),0), 19))} -> NA | O10: {=IF(ISBLANK($AQ10), "", INDEX([2]SalmonProps!$A$2:$AA$10001,MATCH(1,($A10=[2]SalmonProps!$A$2:$A$10001)*(1=[2]SalmonProps!$C$2:$C$10001)*(1=[2]SalmonProps!$D$2:$D$10001)*("A2" = [2]SalmonProps!$B$2:$B$10001)*($AP10 = [2]SalmonProps!$F$2:$F$10001) *($AR10 = [2]SalmonProps!$G$2:$G$10001),0), 19))} -> #N/A | P10: {=IF(ISBLANK($AQ10), "", INDEX([2]SalmonProps!$A$2:$AA$10001,MATCH(1,($A10=[2]SalmonProps!$A$2:$A$10001)*(2=[2]SalmonProps!$C$2:$C$10001)*(1=[2]SalmonProps!$D$2:$D$10001)*("A2" = [2]SalmonProps!$B$2:$B$10001)*($AP10 = [2]SalmonProps!$F$2:$F$10001) *($AR10 = [2]SalmonProps!$G$2:$G$10001),0), 19))} -> #N/A | Q10: {=IF(ISBLANK($AQ10), "", INDEX([2]SalmonProps!$A$2:$AA$10001,MATCH(1,($A10=[2]SalmonProps!$A$2:$A$10001)*(3=[2]SalmonProps!$C$2:$C$10001)*(1=[2]SalmonProps!$D$2:$D$10001)*("A2" = [2]SalmonProps!$B$2:$B$10001)*($AP10 = [2]SalmonProps!$F$2:$F$10001) *($AR10 = [2]SalmonProps!$G$2:$G$10001),0), 19))} -> #N/A | R10: {=IF(ISBLANK($AQ10), "", INDEX([2]SalmonProps!$A$2:$AA$10001,MATCH(1,($A10=[2]SalmonProps!$A$2:$A$10001)*(1=[2]SalmonProps!$C$2:$C$10001)*(1=[2]SalmonProps!$D$2:$D$10001)*("A1" = [2]SalmonProps!$B$2:$B$10001)*($AP10 = [2]SalmonProps!$F$2:$F$10001) *($AR10 = [2]SalmonProps!$G$2:$G$10001),0), 18))} -> NA | S10: {=IF(ISBLANK($AQ10), "", INDEX([2]SalmonProps!$A$2:$AA$10001,MATCH(1,($A10=[2]SalmonProps!$A$2:$A$10001)*(1=[2]SalmonProps!$C$2:$C$10001)*(2=[2]SalmonProps!$D$2:$D$10001)*("A1" = [2]SalmonProps!$B$2:$B$10001)*($AP10 = [2]SalmonProps!$F$2:$F$10001) *($AR10 = [2]SalmonProps!$G$2:$G$10001),0), 18))} -> NA | T10: {=IF(ISBLANK($AQ10), "", INDEX([2]SalmonProps!$A$2:$AA$10001,MATCH(1,($A10=[2]SalmonProps!$A$2:$A$10001)*(1=[2]SalmonProps!$C$2:$C$10001)*("1&2"=[2]SalmonProps!$D$2:$D$10001)*("A1" = [2]SalmonProps!$B$2:$B$10001)*($AP10 = [2]SalmonProps!$F$2:$F$10001) *($AR10 = [2]SalmonProps!$G$2:$G$10001),0), 18))} -> NA | U10: {=IF(ISBLANK($AQ10), "", INDEX([2]SalmonProps!$A$2:$AA$10001,MATCH(1,($A10=[2]SalmonProps!$A$2:$A$10001)*(2=[2]SalmonProps!$C$2:$C$10001)*(3=[2]SalmonProps!$D$2:$D$10001)*("A1" = [2]SalmonProps!$B$2:$B$10001)*($AP10 = [2]SalmonProps!$F$2:$F$10001) *($AR10 = [2]SalmonProps!$G$2:$G$10001),0), 18))} -> NA | V10: {=IF(ISBLANK($AQ10), "", INDEX([2]SalmonProps!$A$2:$AA$10001,MATCH(1,($A10=[2]SalmonProps!$A$2:$A$10001)*(3=[2]SalmonProps!$C$2:$C$10001)*(3=[2]SalmonProps!$D$2:$D$10001)*("A1" = [2]SalmonProps!$B$2:$B$10001)*($AP10 = [2]SalmonProps!$F$2:$F$10001) *($AR10 = [2]SalmonProps!$G$2:$G$10001),0), 18))} -> NA | W10: {=IF(ISBLANK($AQ10), "", INDEX([2]SalmonProps!$A$2:$AA$10001,MATCH(1,($A10=[2]SalmonProps!$A$2:$A$10001)*(1=[2]SalmonProps!$C$2:$C$10001)*(1=[2]SalmonProps!$D$2:$D$10001)*("A2" = [2]SalmonProps!$B$2:$B$10001)*($AP10 = [2]SalmonProps!$F$2:$F$10001) *($AR10 = [2]SalmonProps!$G$2:$G$10001),0), 18))} -> #N/A | X10: {=IF(ISBLANK($AQ10), "", INDEX([2]SalmonProps!$A$2:$AA$10001,MATCH(1,($A10=[2]SalmonProps!$A$2:$A$10001)*(2=[2]SalmonProps!$C$2:$C$10001)*(1=[2]SalmonProps!$D$2:$D$10001)*("A2" = [2]SalmonProps!$B$2:$B$10001)*($AP10 = [2]SalmonProps!$F$2:$F$10001) *($AR10 = [2]SalmonProps!$G$2:$G$10001),0), 18))} -> #N/A | Y10: {=IF(ISBLANK($AQ10), "", INDEX([2]SalmonProps!$A$2:$AA$10001,MATCH(1,($A10=[2]SalmonProps!$A$2:$A$10001)*(3=[2]SalmonProps!$C$2:$C$10001)*(1=[2]SalmonProps!$D$2:$D$10001)*("A2" = [2]SalmonProps!$B$2:$B$10001)*($AP10 = [2]SalmonProps!$F$2:$F$10001) *($AR10 = [2]SalmonProps!$G$2:$G$10001),0), 18))} -> #N/A | Z10: {=IF(ISBLANK($AQ10), "", INDEX([2]SalmonProps!$A$2:$AA$10001,MATCH(1,($A10=[2]SalmonProps!$A$2:$A$10001)*(1=[2]SalmonProps!$C$2:$C$10001)*(1=[2]SalmonProps!$D$2:$D$10001)*("A1" = [2]SalmonProps!$B$2:$B$10001)*($AP10 = [2]SalmonProps!$F$2:$F$10001) *($AR10 = [2]SalmonProps!$G$2:$G$10001),0), 15))} -> 0.0446 | AA10: {=IF(ISBLANK($AQ10), "", INDEX([2]SalmonProps!$A$2:$AA$10001,MATCH(1,($A10=[2]SalmonProps!$A$2:$A$10001)*(1=[2]SalmonProps!$C$2:$C$10001)*(2=[2]SalmonProps!$D$2:$D$10001)*("A1" = [2]SalmonProps!$B$2:$B$10001)*($AP10 = [2]SalmonProps!$F$2:$F$10001) *($AR10 = [2]SalmonProps!$G$2:$G$10001),0), 15))} -> 0.0206 | AB10: {=IF(ISBLANK($AQ10), "", INDEX([2]SalmonProps!$A$2:$AA$10001,MATCH(1,($A10=[2]SalmonProps!$A$2:$A$10001)*(1=[2]SalmonProps!$C$2:$C$10001)*("1&2"=[2]SalmonProps!$D$2:$D$10001)*("A1" = [2]SalmonProps!$B$2:$B$10001)*($AP10 = [2]SalmonProps!$F$2:$F$10001) *($AR10 = [2]SalmonProps!$G$2:$G$10001),0), 15))} -> 0.0274 | AC10: {=IF(ISBLANK($AQ10), "", INDEX([2]SalmonProps!$A$2:$AA$10001,MATCH(1,($A10=[2]SalmonProps!$A$2:$A$10001)*(2=[2]SalmonProps!$C$2:$C$10001)*(3=[2]SalmonProps!$D$2:$D$10001)*("A1" = [2]SalmonProps!$B$2:$B$10001)*($AP10 = [2]SalmonProps!$F$2:$F$10001) *($AR10 = [2]SalmonProps!$G$2:$G$10001),0), 15))} -> 0.2428 | AD10: {=IF(ISBLANK($AQ10), "", INDEX([2]SalmonProps!$A$2:$AA$10001,MATCH(1,($A10=[2]SalmonProps!$A$2:$A$10001)*(3=[2]SalmonProps!$C$2:$C$10001)*(3=[2]SalmonProps!$D$2:$D$10001)*("A1" = [2]SalmonProps!$B$2:$B$10001)*($AP10 = [2]SalmonProps!$F$2:$F$10001) *($AR10 = [2]SalmonProps!$G$2:$G$10001),0), 15))} -> 0.4004 | AE10: 0.0639 | AF10: 0.0632 | AG10: 0.2357 | AH10: {=IF(ISBLANK($AQ10), "", INDEX([2]SalmonProps!$A$2:$AA$10001,MATCH(1,($A10=[2]SalmonProps!$A$2:$A$10001)*($AP10 = [2]SalmonProps!$F$2:$F$10001) *($AR10 = [2]SalmonProps!$G$2:$G$10001),0), 24))} -> NA | AI10: {=IF(ISBLANK($AQ10), "", INDEX([2]SalmonProps!$A$2:$AA$10001,MATCH(1,($A10=[2]SalmonProps!$A$2:$A$10001)*($AP10 = [2]SalmonProps!$F$2:$F$10001) *($AR10 = [2]SalmonProps!$G$2:$G$10001),0), 25))} -> NA | AJ10: {=IF(ISBLANK($AQ10), "", INDEX([2]SalmonProps!$A$2:$AA$10001,MATCH(1,($A10=[2]SalmonProps!$A$2:$A$10001)*($AP10 = [2]SalmonProps!$F$2:$F$10001) *($AR10 = [2]SalmonProps!$G$2:$G$10001),0), 20))} -> 61.4 | AK10: {=IF(ISBLANK($AQ10), "", INDEX([2]SalmonProps!$A$2:$AA$10001,MATCH(1,($A10=[2]SalmonProps!$A$2:$A$10001)*($AP10 = [2]SalmonProps!$F$2:$F$10001) *($AR10 = [2]SalmonProps!$G$2:$G$10001),0), 21))} -> 5 | AL10: {=IF(ISBLANK($AQ10), "", INDEX([2]SalmonProps!$A$2:$AA$10001,MATCH(1,($A10=[2]SalmonProps!$A$2:$A$10001)*($AP10 = [2]SalmonProps!$F$2:$F$10001) *($AR10 = [2]SalmonProps!$G$2:$G$10001),0), 22))} -> 75.1 | AM10: {=IF(ISBLANK($AQ10), "", INDEX([2]SalmonProps!$A$2:$AA$10001,MATCH(1,($A10=[2]SalmonProps!$A$2:$A$10001)*($AP10 = [2]SalmonProps!$F$2:$F$10001) *($AR10 = [2]SalmonProps!$G$2:$G$10001),0), 23))} -> 7.6 | AN10: {=IF(ISBLANK($AQ10), "", INDEX([2]SalmonProps!$A$2:$AA$10001,MATCH(1,($A10=[2]SalmonProps!$A$2:$A$10001)*($AP10 = [2]SalmonProps!$F$2:$F$10001) *($AR10 = [2]SalmonProps!$G$2:$G$10001),0), 26))} -> NA | AO10: {=IF(ISBLANK($AQ10), "", INDEX([2]SalmonProps!$A$2:$AA$10001,MATCH(1,($A10=[2]SalmonProps!$A$2:$A$10001)*($AP10 = [2]SalmonProps!$F$2:$F$10001) *($AR10 = [2]SalmonProps!$G$2:$G$10001),0), 27))} -> NA | AP10: 3 | AQ10: ML - Unweighted | AR10: =INDEX($AT$2:$AU$5, MATCH(AQ10,$AT$2:$AT$5, 0), 2) -> Unweighted
A11: ='[1]Passage Estimates'!$A11 -> 45113 | B11: {=IF(ISBLANK($AQ11), "", INDEX([2]SalmonProps!$A$2:$AA$10001,MATCH(1,($A11=[2]SalmonProps!$A$2:$A$10001)*(1=[2]SalmonProps!$C$2:$C$10001)*(1=[2]SalmonProps!$D$2:$D$10001)*("A1" = [2]SalmonProps!$B$2:$B$10001)*($AP11 = [2]SalmonProps!$F$2:$F$10001) *($AR11 = [2]SalmonProps!$G$2:$G$10001),0), 17))} -> 0 | C11: {=IF(ISBLANK($AQ11), "", INDEX([2]SalmonProps!$A$2:$AA$10001,MATCH(1,($A11=[2]SalmonProps!$A$2:$A$10001)*(1=[2]SalmonProps!$C$2:$C$10001)*(2=[2]SalmonProps!$D$2:$D$10001)*("A1" = [2]SalmonProps!$B$2:$B$10001)*($AP11 = [2]SalmonProps!$F$2:$F$10001) *($AR11 = [2]SalmonProps!$G$2:$G$10001),0), 17))} -> 0 | D11: {=IF(ISBLANK($AQ11), "", INDEX([2]SalmonProps!$A$2:$AA$10001,MATCH(1,($A11=[2]SalmonProps!$A$2:$A$10001)*(1=[2]SalmonProps!$C$2:$C$10001)*("1&2"=[2]SalmonProps!$D$2:$D$10001)*("A1" = [2]SalmonProps!$B$2:$B$10001)*($AP11 = [2]SalmonProps!$F$2:$F$10001) *($AR11 = [2]SalmonProps!$G$2:$G$10001),0), 17))} -> 0 | E11: {=IF(ISBLANK($AQ11), "", INDEX([2]SalmonProps!$A$2:$AA$10001,MATCH(1,($A11=[2]SalmonProps!$A$2:$A$10001)*(2=[2]SalmonProps!$C$2:$C$10001)*(3=[2]SalmonProps!$D$2:$D$10001)*("A1" = [2]SalmonProps!$B$2:$B$10001)*($AP11 = [2]SalmonProps!$F$2:$F$10001) *($AR11 = [2]SalmonProps!$G$2:$G$10001),0), 17))} -> 0.1125 | F11: {=IF(ISBLANK($AQ11), "", INDEX([2]SalmonProps!$A$2:$AA$10001,MATCH(1,($A11=[2]SalmonProps!$A$2:$A$10001)*(3=[2]SalmonProps!$C$2:$C$10001)*(3=[2]SalmonProps!$D$2:$D$10001)*("A1" = [2]SalmonProps!$B$2:$B$10001)*($AP11 = [2]SalmonProps!$F$2:$F$10001) *($AR11 = [2]SalmonProps!$G$2:$G$10001),0), 17))} -> 0.3116 | G11: 0 | H11: 0.0333 | I11: 0.0694 | J11: {=IF(ISBLANK($AQ11), "", INDEX([2]SalmonProps!$A$2:$AA$10001,MATCH(1,($A11=[2]SalmonProps!$A$2:$A$10001)*(1=[2]SalmonProps!$C$2:$C$10001)*(1=[2]SalmonProps!$D$2:$D$10001)*("A1" = [2]SalmonProps!$B$2:$B$10001)*($AP11 = [2]SalmonProps!$F$2:$F$10001) *($AR11 = [2]SalmonProps!$G$2:$G$10001),0), 19))} -> NA | K11: {=IF(ISBLANK($AQ11), "", INDEX([2]SalmonProps!$A$2:$AA$10001,MATCH(1,($A11=[2]SalmonProps!$A$2:$A$10001)*(1=[2]SalmonProps!$C$2:$C$10001)*(2=[2]SalmonProps!$D$2:$D$10001)*("A1" = [2]SalmonProps!$B$2:$B$10001)*($AP11 = [2]SalmonProps!$F$2:$F$10001) *($AR11 = [2]SalmonProps!$G$2:$G$10001),0), 19))} -> NA | L11: {=IF(ISBLANK($AQ11), "", INDEX([2]SalmonProps!$A$2:$AA$10001,MATCH(1,($A11=[2]SalmonProps!$A$2:$A$10001)*(1=[2]SalmonProps!$C$2:$C$10001)*("1&2"=[2]SalmonProps!$D$2:$D$10001)*("A1" = [2]SalmonProps!$B$2:$B$10001)*($AP11 = [2]SalmonProps!$F$2:$F$10001) *($AR11 = [2]SalmonProps!$G$2:$G$10001),0), 19))} -> NA | M11: {=IF(ISBLANK($AQ11), "", INDEX([2]SalmonProps!$A$2:$AA$10001,MATCH(1,($A11=[2]SalmonProps!$A$2:$A$10001)*(2=[2]SalmonProps!$C$2:$C$10001)*(3=[2]SalmonProps!$D$2:$D$10001)*("A1" = [2]SalmonProps!$B$2:$B$10001)*($AP11 = [2]SalmonProps!$F$2:$F$10001) *($AR11 = [2]SalmonProps!$G$2:$G$10001),0), 19))} -> NA | N11: {=IF(ISBLANK($AQ11), "", INDEX([2]SalmonProps!$A$2:$AA$10001,MATCH(1,($A11=[2]SalmonProps!$A$2:$A$10001)*(3=[2]SalmonProps!$C$2:$C$10001)*(3=[2]SalmonProps!$D$2:$D$10001)*("A1" = [2]SalmonProps!$B$2:$B$10001)*($AP11 = [2]SalmonProps!$F$2:$F$10001) *($AR11 = [2]SalmonProps!$G$2:$G$10001),0), 19))} -> NA | O11: {=IF(ISBLANK($AQ11), "", INDEX([2]SalmonProps!$A$2:$AA$10001,MATCH(1,($A11=[2]SalmonProps!$A$2:$A$10001)*(1=[2]SalmonProps!$C$2:$C$10001)*(1=[2]SalmonProps!$D$2:$D$10001)*("A2" = [2]SalmonProps!$B$2:$B$10001)*($AP11 = [2]SalmonProps!$F$2:$F$10001) *($AR11 = [2]SalmonProps!$G$2:$G$10001),0), 19))} -> NA | P11: {=IF(ISBLANK($AQ11), "", INDEX([2]SalmonProps!$A$2:$AA$10001,MATCH(1,($A11=[2]SalmonProps!$A$2:$A$10001)*(2=[2]SalmonProps!$C$2:$C$10001)*(1=[2]SalmonProps!$D$2:$D$10001)*("A2" = [2]SalmonProps!$B$2:$B$10001)*($AP11 = [2]SalmonProps!$F$2:$F$10001) *($AR11 = [2]SalmonProps!$G$2:$G$10001),0), 19))} -> #N/A | Q11: {=IF(ISBLANK($AQ11), "", INDEX([2]SalmonProps!$A$2:$AA$10001,MATCH(1,($A11=[2]SalmonProps!$A$2:$A$10001)*(3=[2]SalmonProps!$C$2:$C$10001)*(1=[2]SalmonProps!$D$2:$D$10001)*("A2" = [2]SalmonProps!$B$2:$B$10001)*($AP11 = [2]SalmonProps!$F$2:$F$10001) *($AR11 = [2]SalmonProps!$G$2:$G$10001),0), 19))} -> #N/A | R11: {=IF(ISBLANK($AQ11), "", INDEX([2]SalmonProps!$A$2:$AA$10001,MATCH(1,($A11=[2]SalmonProps!$A$2:$A$10001)*(1=[2]SalmonProps!$C$2:$C$10001)*(1=[2]SalmonProps!$D$2:$D$10001)*("A1" = [2]SalmonProps!$B$2:$B$10001)*($AP11 = [2]SalmonProps!$F$2:$F$10001) *($AR11 = [2]SalmonProps!$G$2:$G$10001),0), 18))} -> NA | S11: {=IF(ISBLANK($AQ11), "", INDEX([2]SalmonProps!$A$2:$AA$10001,MATCH(1,($A11=[2]SalmonProps!$A$2:$A$10001)*(1=[2]SalmonProps!$C$2:$C$10001)*(2=[2]SalmonProps!$D$2:$D$10001)*("A1" = [2]SalmonProps!$B$2:$B$10001)*($AP11 = [2]SalmonProps!$F$2:$F$10001) *($AR11 = [2]SalmonProps!$G$2:$G$10001),0), 18))} -> NA | T11: {=IF(ISBLANK($AQ11), "", INDEX([2]SalmonProps!$A$2:$AA$10001,MATCH(1,($A11=[2]SalmonProps!$A$2:$A$10001)*(1=[2]SalmonProps!$C$2:$C$10001)*("1&2"=[2]SalmonProps!$D$2:$D$10001)*("A1" = [2]SalmonProps!$B$2:$B$10001)*($AP11 = [2]SalmonProps!$F$2:$F$10001) *($AR11 = [2]SalmonProps!$G$2:$G$10001),0), 18))} -> NA | U11: {=IF(ISBLANK($AQ11), "", INDEX([2]SalmonProps!$A$2:$AA$10001,MATCH(1,($A11=[2]SalmonProps!$A$2:$A$10001)*(2=[2]SalmonProps!$C$2:$C$10001)*(3=[2]SalmonProps!$D$2:$D$10001)*("A1" = [2]SalmonProps!$B$2:$B$10001)*($AP11 = [2]SalmonProps!$F$2:$F$10001) *($AR11 = [2]SalmonProps!$G$2:$G$10001),0), 18))} -> NA | V11: {=IF(ISBLANK($AQ11), "", INDEX([2]SalmonProps!$A$2:$AA$10001,MATCH(1,($A11=[2]SalmonProps!$A$2:$A$10001)*(3=[2]SalmonProps!$C$2:$C$10001)*(3=[2]SalmonProps!$D$2:$D$10001)*("A1" = [2]SalmonProps!$B$2:$B$10001)*($AP11 = [2]SalmonProps!$F$2:$F$10001) *($AR11 = [2]SalmonProps!$G$2:$G$10001),0), 18))} -> NA | W11: {=IF(ISBLANK($AQ11), "", INDEX([2]SalmonProps!$A$2:$AA$10001,MATCH(1,($A11=[2]SalmonProps!$A$2:$A$10001)*(1=[2]SalmonProps!$C$2:$C$10001)*(1=[2]SalmonProps!$D$2:$D$10001)*("A2" = [2]SalmonProps!$B$2:$B$10001)*($AP11 = [2]SalmonProps!$F$2:$F$10001) *($AR11 = [2]SalmonProps!$G$2:$G$10001),0), 18))} -> NA | X11: {=IF(ISBLANK($AQ11), "", INDEX([2]SalmonProps!$A$2:$AA$10001,MATCH(1,($A11=[2]SalmonProps!$A$2:$A$10001)*(2=[2]SalmonProps!$C$2:$C$10001)*(1=[2]SalmonProps!$D$2:$D$10001)*("A2" = [2]SalmonProps!$B$2:$B$10001)*($AP11 = [2]SalmonProps!$F$2:$F$10001) *($AR11 = [2]SalmonProps!$G$2:$G$10001),0), 18))} -> #N/A | Y11: {=IF(ISBLANK($AQ11), "", INDEX([2]SalmonProps!$A$2:$AA$10001,MATCH(1,($A11=[2]SalmonProps!$A$2:$A$10001)*(3=[2]SalmonProps!$C$2:$C$10001)*(1=[2]SalmonProps!$D$2:$D$10001)*("A2" = [2]SalmonProps!$B$2:$B$10001)*($AP11 = [2]SalmonProps!$F$2:$F$10001) *($AR11 = [2]SalmonProps!$G$2:$G$10001),0), 18))} -> #N/A | Z11: {=IF(ISBLANK($AQ11), "", INDEX([2]SalmonProps!$A$2:$AA$10001,MATCH(1,($A11=[2]SalmonProps!$A$2:$A$10001)*(1=[2]SalmonProps!$C$2:$C$10001)*(1=[2]SalmonProps!$D$2:$D$10001)*("A1" = [2]SalmonProps!$B$2:$B$10001)*($AP11 = [2]SalmonProps!$F$2:$F$10001) *($AR11 = [2]SalmonProps!$G$2:$G$10001),0), 15))} -> 0.0618 | AA11: {=IF(ISBLANK($AQ11), "", INDEX([2]SalmonProps!$A$2:$AA$10001,MATCH(1,($A11=[2]SalmonProps!$A$2:$A$10001)*(1=[2]SalmonProps!$C$2:$C$10001)*(2=[2]SalmonProps!$D$2:$D$10001)*("A1" = [2]SalmonProps!$B$2:$B$10001)*($AP11 = [2]SalmonProps!$F$2:$F$10001) *($AR11 = [2]SalmonProps!$G$2:$G$10001),0), 15))} -> 0.0056 | AB11: {=IF(ISBLANK($AQ11), "", INDEX([2]SalmonProps!$A$2:$AA$10001,MATCH(1,($A11=[2]SalmonProps!$A$2:$A$10001)*(1=[2]SalmonProps!$C$2:$C$10001)*("1&2"=[2]SalmonProps!$D$2:$D$10001)*("A1" = [2]SalmonProps!$B$2:$B$10001)*($AP11 = [2]SalmonProps!$F$2:$F$10001) *($AR11 = [2]SalmonProps!$G$2:$G$10001),0), 15))} -> 0.0325 | AC11: {=IF(ISBLANK($AQ11), "", INDEX([2]SalmonProps!$A$2:$AA$10001,MATCH(1,($A11=[2]SalmonProps!$A$2:$A$10001)*(2=[2]SalmonProps!$C$2:$C$10001)*(3=[2]SalmonProps!$D$2:$D$10001)*("A1" = [2]SalmonProps!$B$2:$B$10001)*($AP11 = [2]SalmonProps!$F$2:$F$10001) *($AR11 = [2]SalmonProps!$G$2:$G$10001),0), 15))} -> 0.1761 | AD11: {=IF(ISBLANK($AQ11), "", INDEX([2]SalmonProps!$A$2:$AA$10001,MATCH(1,($A11=[2]SalmonProps!$A$2:$A$10001)*(3=[2]SalmonProps!$C$2:$C$10001)*(3=[2]SalmonProps!$D$2:$D$10001)*("A1" = [2]SalmonProps!$B$2:$B$10001)*($AP11 = [2]SalmonProps!$F$2:$F$10001) *($AR11 = [2]SalmonProps!$G$2:$G$10001),0), 15))} -> 0.4656 | AE11: 0.0639 | AF11: 0.0632 | AG11: 0.2357 | AH11: {=IF(ISBLANK($AQ11), "", INDEX([2]SalmonProps!$A$2:$AA$10001,MATCH(1,($A11=[2]SalmonProps!$A$2:$A$10001)*($AP11 = [2]SalmonProps!$F$2:$F$10001) *($AR11 = [2]SalmonProps!$G$2:$G$10001),0), 24))} -> NA | AI11: {=IF(ISBLANK($AQ11), "", INDEX([2]SalmonProps!$A$2:$AA$10001,MATCH(1,($A11=[2]SalmonProps!$A$2:$A$10001)*($AP11 = [2]SalmonProps!$F$2:$F$10001) *($AR11 = [2]SalmonProps!$G$2:$G$10001),0), 25))} -> NA | AJ11: {=IF(ISBLANK($AQ11), "", INDEX([2]SalmonProps!$A$2:$AA$10001,MATCH(1,($A11=[2]SalmonProps!$A$2:$A$10001)*($AP11 = [2]SalmonProps!$F$2:$F$10001) *($AR11 = [2]SalmonProps!$G$2:$G$10001),0), 20))} -> 61.4 | AK11: {=IF(ISBLANK($AQ11), "", INDEX([2]SalmonProps!$A$2:$AA$10001,MATCH(1,($A11=[2]SalmonProps!$A$2:$A$10001)*($AP11 = [2]SalmonProps!$F$2:$F$10001) *($AR11 = [2]SalmonProps!$G$2:$G$10001),0), 21))} -> 5 | AL11: {=IF(ISBLANK($AQ11), "", INDEX([2]SalmonProps!$A$2:$AA$10001,MATCH(1,($A11=[2]SalmonProps!$A$2:$A$10001)*($AP11 = [2]SalmonProps!$F$2:$F$10001) *($AR11 = [2]SalmonProps!$G$2:$G$10001),0), 22))} -> 75.1 | AM11: {=IF(ISBLANK($AQ11), "", INDEX([2]SalmonProps!$A$2:$AA$10001,MATCH(1,($A11=[2]SalmonProps!$A$2:$A$10001)*($AP11 = [2]SalmonProps!$F$2:$F$10001) *($AR11 = [2]SalmonProps!$G$2:$G$10001),0), 23))} -> 7.6 | AN11: {=IF(ISBLANK($AQ11), "", INDEX([2]SalmonProps!$A$2:$AA$10001,MATCH(1,($A11=[2]SalmonProps!$A$2:$A$10001)*($AP11 = [2]SalmonProps!$F$2:$F$10001) *($AR11 = [2]SalmonProps!$G$2:$G$10001),0), 26))} -> NA | AO11: {=IF(ISBLANK($AQ11), "", INDEX([2]SalmonProps!$A$2:$AA$10001,MATCH(1,($A11=[2]SalmonProps!$A$2:$A$10001)*($AP11 = [2]SalmonProps!$F$2:$F$10001) *($AR11 = [2]SalmonProps!$G$2:$G$10001),0), 27))} -> NA | AP11: 3 | AQ11: ML - Unweighted | AR11: =INDEX($AT$2:$AU$5, MATCH(AQ11,$AT$2:$AT$5, 0), 2) -> Unweighted
